<?xml version="1.0" encoding="UTF-8"?>
<!DOCTYPE html PUBLIC "-//W3C//DTD XHTML 1.0 Strict//EN" "http://www.w3.org/TR/xhtml1/DTD/xhtml1-strict.dtd">
<html xmlns="http://www.w3.org/1999/xhtml">
<head>
    <title>自动化测试报告</title>
    <meta name="generator" content="HTMLTestRunner 0.8.2.2"/>
    <meta http-equiv="Content-Type" content="text/html; charset=UTF-8"/>
    <link href="http://libs.baidu.com/bootstrap/3.0.3/css/bootstrap.min.css" rel="stylesheet">
    <script src="http://libs.baidu.com/jquery/2.0.0/jquery.min.js"></script>
    <script src="http://libs.baidu.com/bootstrap/3.0.3/js/bootstrap.min.js"></script>
    
<style type="text/css" media="screen">
body        { font-family: Microsoft YaHei,Tahoma,arial,helvetica,sans-serif;padding: 20px; font-size: 120%; }
table       { font-size: 100%; }
/* -- heading ---------------------------------------------------------------------- */
.heading {
    margin-top: 0ex;
    margin-bottom: 1ex;
}
.heading .description {
    margin-top: 4ex;
    margin-bottom: 6ex;
}
/* -- report ------------------------------------------------------------------------ */
#total_row  { font-weight: bold; }
.passCase   { color: #5cb85c; }
.failCase   { color: #d9534f; font-weight: bold; }
.errorCase  { color: #f0ad4e; font-weight: bold; }
.hiddenRow  { display: none; }
.testcase   { margin-left: 2em; }
</style>

</head>
<body >
<script language="javascript" type="text/javascript">
output_list = Array();
/*level 调整增加只显示通过用例的分类 --Findyou
0:Summary //all hiddenRow
1:Failed  //pt hiddenRow, ft none
2:Pass    //pt none, ft hiddenRow
3:All     //pt none, ft none
*/
function showCase(level) {
    trs = document.getElementsByTagName("tr");
    for (var i = 0; i < trs.length; i++) {
        tr = trs[i];
        id = tr.id;
        if (id.substr(0,2) == 'ft') {
            if (level == 2 || level == 0 ) {
                tr.className = 'hiddenRow';
            }
            else {
                tr.className = '';
            }
        }
        if (id.substr(0,2) == 'pt') {
            if (level < 2) {
                tr.className = 'hiddenRow';
            }
            else {
                tr.className = '';
            }
        }
    }
    //加入【详细】切换文字变化 --Findyou
    detail_class=document.getElementsByClassName('detail');
	//console.log(detail_class.length)
	if (level == 3) {
		for (var i = 0; i < detail_class.length; i++){
			detail_class[i].innerHTML="收起"
		}
	}
	else{
			for (var i = 0; i < detail_class.length; i++){
			detail_class[i].innerHTML="详细"
		}
	}
}
function showClassDetail(cid, count) {
    var id_list = Array(count);
    var toHide = 1;
    for (var i = 0; i < count; i++) {
        //ID修改 点 为 下划线 -Findyou
        tid0 = 't' + cid.substr(1) + '_' + (i+1);
        tid = 'f' + tid0;
        tr = document.getElementById(tid);
        if (!tr) {
            tid = 'p' + tid0;
            tr = document.getElementById(tid);
        }
        id_list[i] = tid;
        if (tr.className) {
            toHide = 0;
        }
    }
    for (var i = 0; i < count; i++) {
        tid = id_list[i];
        //修改点击无法收起的BUG，加入【详细】切换文字变化 --Findyou
        if (toHide) {
            document.getElementById(tid).className = 'hiddenRow';
            document.getElementById(cid).innerText = "详细"
        }
        else {
            document.getElementById(tid).className = '';
            document.getElementById(cid).innerText = "收起"
        }
    }
}
function html_escape(s) {
    s = s.replace(/&/g,'&amp;');
    s = s.replace(/</g,'&lt;');
    s = s.replace(/>/g,'&gt;');
    return s;
}
</script>
<div class='heading'>
<h1 style="font-family: Microsoft YaHei">自动化测试报告</h1>
<p class='attribute'><strong>测试人员 : </strong> ss</p>
<p class='attribute'><strong>开始时间 : </strong> 2021-05-25 14:00:29</p>
<p class='attribute'><strong>合计耗时 : </strong> 0:00:55.692926</p>
<p class='attribute'><strong>测试结果 : </strong> 共 33，错误 33，通过率= 0.00%</p>

<p class='description'>这是一个美轮美奂的报告</p>
</div>


<p id='show_detail_line'>
<a class="btn btn-primary" href='javascript:showCase(0)'>概要{ 0.00% }</a>
<a class="btn btn-danger" href='javascript:showCase(1)'>失败{ 0 }</a>
<a class="btn btn-success" href='javascript:showCase(2)'>通过{ 0 }</a>
<a class="btn btn-info" href='javascript:showCase(3)'>所有{ 33 }</a>
</p>
<table id='result_table' class="table table-condensed table-bordered table-hover">
<colgroup>
<col align='left' />
<col align='right' />
<col align='right' />
<col align='right' />
<col align='right' />
<col align='right' />
</colgroup>
<tr id='header_row' class="text-center success" style="font-weight: bold;font-size: 16px;">
    <td>用例集/测试用例</td>
    <td>总计</td>
    <td>通过</td>
    <td>失败</td>
    <td>错误</td>
    <td>详细</td>
</tr>

<tr class='errorClass warning'>
    <td>test_01_login.TestLogin</td>
    <td class="text-center">6</td>
    <td class="text-center">0</td>
    <td class="text-center">0</td>
    <td class="text-center">6</td>
    <td class="text-center"><a href="javascript:showClassDetail('c1',6)" class="detail" id='c1'>详细</a></td>
</tr>

<tr id='ft1_1' class='none'>
    <td class='errorCase'><div class='testcase'>test_login_1: 手机号为空</div></td>
    <td colspan='5' align='center'>
    <!--默认收起错误信息 -Findyou
    <button id='btn_ft1_1' type="button"  class="btn btn-danger btn-xs collapsed" data-toggle="collapse" data-target='#div_ft1_1'>错误</button>
    <div id='div_ft1_1' class="collapse">  -->
    <!-- 默认展开错误信息 -Findyou -->
    <button id='btn_ft1_1' type="button"  class="btn btn-danger btn-xs" data-toggle="collapse" data-target='#div_ft1_1'>错误</button>
    <div id='div_ft1_1' class="collapse in" align="left">
    <pre>
    
ft1_1: http://ssssss:9101/api/auth/login
Traceback (most recent call last):
  File "D:\soft\python\lib\site-packages\urllib3\connection.py", line 159, in _new_conn
    conn = connection.create_connection(
  File "D:\soft\python\lib\site-packages\urllib3\util\connection.py", line 61, in create_connection
    for res in socket.getaddrinfo(host, port, family, socket.SOCK_STREAM):
  File "D:\soft\python\lib\socket.py", line 918, in getaddrinfo
    for res in _socket.getaddrinfo(host, port, family, type, proto, flags):
socket.gaierror: [Errno 11001] getaddrinfo failed

During handling of the above exception, another exception occurred:

Traceback (most recent call last):
  File "D:\soft\python\lib\site-packages\urllib3\connectionpool.py", line 670, in urlopen
    httplib_response = self._make_request(
  File "D:\soft\python\lib\site-packages\urllib3\connectionpool.py", line 392, in _make_request
    conn.request(method, url, **httplib_request_kw)
  File "D:\soft\python\lib\http\client.py", line 1230, in request
    self._send_request(method, url, body, headers, encode_chunked)
  File "D:\soft\python\lib\http\client.py", line 1276, in _send_request
    self.endheaders(body, encode_chunked=encode_chunked)
  File "D:\soft\python\lib\http\client.py", line 1225, in endheaders
    self._send_output(message_body, encode_chunked=encode_chunked)
  File "D:\soft\python\lib\http\client.py", line 1004, in _send_output
    self.send(msg)
  File "D:\soft\python\lib\http\client.py", line 944, in send
    self.connect()
  File "D:\soft\python\lib\site-packages\urllib3\connection.py", line 187, in connect
    conn = self._new_conn()
  File "D:\soft\python\lib\site-packages\urllib3\connection.py", line 171, in _new_conn
    raise NewConnectionError(
urllib3.exceptions.NewConnectionError: &lt;urllib3.connection.HTTPConnection object at 0x0000024C2ED2C7F0&gt;: Failed to establish a new connection: [Errno 11001] getaddrinfo failed

During handling of the above exception, another exception occurred:

Traceback (most recent call last):
  File "D:\soft\python\lib\site-packages\requests\adapters.py", line 439, in send
    resp = conn.urlopen(
  File "D:\soft\python\lib\site-packages\urllib3\connectionpool.py", line 724, in urlopen
    retries = retries.increment(
  File "D:\soft\python\lib\site-packages\urllib3\util\retry.py", line 439, in increment
    raise MaxRetryError(_pool, url, error or ResponseError(cause))
urllib3.exceptions.MaxRetryError: HTTPConnectionPool(host='ssssss', port=9101): Max retries exceeded with url: /api/auth/login (Caused by NewConnectionError('&lt;urllib3.connection.HTTPConnection object at 0x0000024C2ED2C7F0&gt;: Failed to establish a new connection: [Errno 11001] getaddrinfo failed'))

During handling of the above exception, another exception occurred:

Traceback (most recent call last):
  File "D:\python_test\libs\ddt.py", line 145, in wrapper
    return func(self, *args, **kwargs)
  File "D:\python_test\cases\test_01_login.py", line 40, in test_login
    res = self.do_request.send(url=new_url,  # url地址
  File "D:\python_test\scripts\handle_request.py", line 61, in send
    res = self.one_session.request(method, url, json=data, **kwargs)
  File "D:\soft\python\lib\site-packages\requests\sessions.py", line 530, in request
    resp = self.send(prep, **send_kwargs)
  File "D:\soft\python\lib\site-packages\requests\sessions.py", line 643, in send
    r = adapter.send(request, **kwargs)
  File "D:\soft\python\lib\site-packages\requests\adapters.py", line 516, in send
    raise ConnectionError(e, request=request)
requests.exceptions.ConnectionError: HTTPConnectionPool(host='ssssss', port=9101): Max retries exceeded with url: /api/auth/login (Caused by NewConnectionError('&lt;urllib3.connection.HTTPConnection object at 0x0000024C2ED2C7F0&gt;: Failed to establish a new connection: [Errno 11001] getaddrinfo failed'))


    </pre>
    </div>
    </td>
</tr>

<tr id='ft1_2' class='none'>
    <td class='errorCase'><div class='testcase'>test_login_2: 密码为空</div></td>
    <td colspan='5' align='center'>
    <!--默认收起错误信息 -Findyou
    <button id='btn_ft1_2' type="button"  class="btn btn-danger btn-xs collapsed" data-toggle="collapse" data-target='#div_ft1_2'>错误</button>
    <div id='div_ft1_2' class="collapse">  -->
    <!-- 默认展开错误信息 -Findyou -->
    <button id='btn_ft1_2' type="button"  class="btn btn-danger btn-xs" data-toggle="collapse" data-target='#div_ft1_2'>错误</button>
    <div id='div_ft1_2' class="collapse in" align="left">
    <pre>
    
ft1_2: http://ssssss:9101/api/auth/login
Traceback (most recent call last):
  File "D:\soft\python\lib\site-packages\urllib3\connection.py", line 159, in _new_conn
    conn = connection.create_connection(
  File "D:\soft\python\lib\site-packages\urllib3\util\connection.py", line 61, in create_connection
    for res in socket.getaddrinfo(host, port, family, socket.SOCK_STREAM):
  File "D:\soft\python\lib\socket.py", line 918, in getaddrinfo
    for res in _socket.getaddrinfo(host, port, family, type, proto, flags):
socket.gaierror: [Errno 11001] getaddrinfo failed

During handling of the above exception, another exception occurred:

Traceback (most recent call last):
  File "D:\soft\python\lib\site-packages\urllib3\connectionpool.py", line 670, in urlopen
    httplib_response = self._make_request(
  File "D:\soft\python\lib\site-packages\urllib3\connectionpool.py", line 392, in _make_request
    conn.request(method, url, **httplib_request_kw)
  File "D:\soft\python\lib\http\client.py", line 1230, in request
    self._send_request(method, url, body, headers, encode_chunked)
  File "D:\soft\python\lib\http\client.py", line 1276, in _send_request
    self.endheaders(body, encode_chunked=encode_chunked)
  File "D:\soft\python\lib\http\client.py", line 1225, in endheaders
    self._send_output(message_body, encode_chunked=encode_chunked)
  File "D:\soft\python\lib\http\client.py", line 1004, in _send_output
    self.send(msg)
  File "D:\soft\python\lib\http\client.py", line 944, in send
    self.connect()
  File "D:\soft\python\lib\site-packages\urllib3\connection.py", line 187, in connect
    conn = self._new_conn()
  File "D:\soft\python\lib\site-packages\urllib3\connection.py", line 171, in _new_conn
    raise NewConnectionError(
urllib3.exceptions.NewConnectionError: &lt;urllib3.connection.HTTPConnection object at 0x0000024C2ED2C880&gt;: Failed to establish a new connection: [Errno 11001] getaddrinfo failed

During handling of the above exception, another exception occurred:

Traceback (most recent call last):
  File "D:\soft\python\lib\site-packages\requests\adapters.py", line 439, in send
    resp = conn.urlopen(
  File "D:\soft\python\lib\site-packages\urllib3\connectionpool.py", line 724, in urlopen
    retries = retries.increment(
  File "D:\soft\python\lib\site-packages\urllib3\util\retry.py", line 439, in increment
    raise MaxRetryError(_pool, url, error or ResponseError(cause))
urllib3.exceptions.MaxRetryError: HTTPConnectionPool(host='ssssss', port=9101): Max retries exceeded with url: /api/auth/login (Caused by NewConnectionError('&lt;urllib3.connection.HTTPConnection object at 0x0000024C2ED2C880&gt;: Failed to establish a new connection: [Errno 11001] getaddrinfo failed'))

During handling of the above exception, another exception occurred:

Traceback (most recent call last):
  File "D:\python_test\libs\ddt.py", line 145, in wrapper
    return func(self, *args, **kwargs)
  File "D:\python_test\cases\test_01_login.py", line 40, in test_login
    res = self.do_request.send(url=new_url,  # url地址
  File "D:\python_test\scripts\handle_request.py", line 61, in send
    res = self.one_session.request(method, url, json=data, **kwargs)
  File "D:\soft\python\lib\site-packages\requests\sessions.py", line 530, in request
    resp = self.send(prep, **send_kwargs)
  File "D:\soft\python\lib\site-packages\requests\sessions.py", line 643, in send
    r = adapter.send(request, **kwargs)
  File "D:\soft\python\lib\site-packages\requests\adapters.py", line 516, in send
    raise ConnectionError(e, request=request)
requests.exceptions.ConnectionError: HTTPConnectionPool(host='ssssss', port=9101): Max retries exceeded with url: /api/auth/login (Caused by NewConnectionError('&lt;urllib3.connection.HTTPConnection object at 0x0000024C2ED2C880&gt;: Failed to establish a new connection: [Errno 11001] getaddrinfo failed'))


    </pre>
    </div>
    </td>
</tr>

<tr id='ft1_3' class='none'>
    <td class='errorCase'><div class='testcase'>test_login_3: 密码错误</div></td>
    <td colspan='5' align='center'>
    <!--默认收起错误信息 -Findyou
    <button id='btn_ft1_3' type="button"  class="btn btn-danger btn-xs collapsed" data-toggle="collapse" data-target='#div_ft1_3'>错误</button>
    <div id='div_ft1_3' class="collapse">  -->
    <!-- 默认展开错误信息 -Findyou -->
    <button id='btn_ft1_3' type="button"  class="btn btn-danger btn-xs" data-toggle="collapse" data-target='#div_ft1_3'>错误</button>
    <div id='div_ft1_3' class="collapse in" align="left">
    <pre>
    
ft1_3: http://ssssss:9101/api/auth/login
Traceback (most recent call last):
  File "D:\soft\python\lib\site-packages\urllib3\connection.py", line 159, in _new_conn
    conn = connection.create_connection(
  File "D:\soft\python\lib\site-packages\urllib3\util\connection.py", line 61, in create_connection
    for res in socket.getaddrinfo(host, port, family, socket.SOCK_STREAM):
  File "D:\soft\python\lib\socket.py", line 918, in getaddrinfo
    for res in _socket.getaddrinfo(host, port, family, type, proto, flags):
socket.gaierror: [Errno 11001] getaddrinfo failed

During handling of the above exception, another exception occurred:

Traceback (most recent call last):
  File "D:\soft\python\lib\site-packages\urllib3\connectionpool.py", line 670, in urlopen
    httplib_response = self._make_request(
  File "D:\soft\python\lib\site-packages\urllib3\connectionpool.py", line 392, in _make_request
    conn.request(method, url, **httplib_request_kw)
  File "D:\soft\python\lib\http\client.py", line 1230, in request
    self._send_request(method, url, body, headers, encode_chunked)
  File "D:\soft\python\lib\http\client.py", line 1276, in _send_request
    self.endheaders(body, encode_chunked=encode_chunked)
  File "D:\soft\python\lib\http\client.py", line 1225, in endheaders
    self._send_output(message_body, encode_chunked=encode_chunked)
  File "D:\soft\python\lib\http\client.py", line 1004, in _send_output
    self.send(msg)
  File "D:\soft\python\lib\http\client.py", line 944, in send
    self.connect()
  File "D:\soft\python\lib\site-packages\urllib3\connection.py", line 187, in connect
    conn = self._new_conn()
  File "D:\soft\python\lib\site-packages\urllib3\connection.py", line 171, in _new_conn
    raise NewConnectionError(
urllib3.exceptions.NewConnectionError: &lt;urllib3.connection.HTTPConnection object at 0x0000024C2ED2C7F0&gt;: Failed to establish a new connection: [Errno 11001] getaddrinfo failed

During handling of the above exception, another exception occurred:

Traceback (most recent call last):
  File "D:\soft\python\lib\site-packages\requests\adapters.py", line 439, in send
    resp = conn.urlopen(
  File "D:\soft\python\lib\site-packages\urllib3\connectionpool.py", line 724, in urlopen
    retries = retries.increment(
  File "D:\soft\python\lib\site-packages\urllib3\util\retry.py", line 439, in increment
    raise MaxRetryError(_pool, url, error or ResponseError(cause))
urllib3.exceptions.MaxRetryError: HTTPConnectionPool(host='ssssss', port=9101): Max retries exceeded with url: /api/auth/login (Caused by NewConnectionError('&lt;urllib3.connection.HTTPConnection object at 0x0000024C2ED2C7F0&gt;: Failed to establish a new connection: [Errno 11001] getaddrinfo failed'))

During handling of the above exception, another exception occurred:

Traceback (most recent call last):
  File "D:\python_test\libs\ddt.py", line 145, in wrapper
    return func(self, *args, **kwargs)
  File "D:\python_test\cases\test_01_login.py", line 40, in test_login
    res = self.do_request.send(url=new_url,  # url地址
  File "D:\python_test\scripts\handle_request.py", line 61, in send
    res = self.one_session.request(method, url, json=data, **kwargs)
  File "D:\soft\python\lib\site-packages\requests\sessions.py", line 530, in request
    resp = self.send(prep, **send_kwargs)
  File "D:\soft\python\lib\site-packages\requests\sessions.py", line 643, in send
    r = adapter.send(request, **kwargs)
  File "D:\soft\python\lib\site-packages\requests\adapters.py", line 516, in send
    raise ConnectionError(e, request=request)
requests.exceptions.ConnectionError: HTTPConnectionPool(host='ssssss', port=9101): Max retries exceeded with url: /api/auth/login (Caused by NewConnectionError('&lt;urllib3.connection.HTTPConnection object at 0x0000024C2ED2C7F0&gt;: Failed to establish a new connection: [Errno 11001] getaddrinfo failed'))


    </pre>
    </div>
    </td>
</tr>

<tr id='ft1_4' class='none'>
    <td class='errorCase'><div class='testcase'>test_login_4: 手机号错误</div></td>
    <td colspan='5' align='center'>
    <!--默认收起错误信息 -Findyou
    <button id='btn_ft1_4' type="button"  class="btn btn-danger btn-xs collapsed" data-toggle="collapse" data-target='#div_ft1_4'>错误</button>
    <div id='div_ft1_4' class="collapse">  -->
    <!-- 默认展开错误信息 -Findyou -->
    <button id='btn_ft1_4' type="button"  class="btn btn-danger btn-xs" data-toggle="collapse" data-target='#div_ft1_4'>错误</button>
    <div id='div_ft1_4' class="collapse in" align="left">
    <pre>
    
ft1_4: http://ssssss:9101/api/auth/login
Traceback (most recent call last):
  File "D:\soft\python\lib\site-packages\urllib3\connection.py", line 159, in _new_conn
    conn = connection.create_connection(
  File "D:\soft\python\lib\site-packages\urllib3\util\connection.py", line 61, in create_connection
    for res in socket.getaddrinfo(host, port, family, socket.SOCK_STREAM):
  File "D:\soft\python\lib\socket.py", line 918, in getaddrinfo
    for res in _socket.getaddrinfo(host, port, family, type, proto, flags):
socket.gaierror: [Errno 11001] getaddrinfo failed

During handling of the above exception, another exception occurred:

Traceback (most recent call last):
  File "D:\soft\python\lib\site-packages\urllib3\connectionpool.py", line 670, in urlopen
    httplib_response = self._make_request(
  File "D:\soft\python\lib\site-packages\urllib3\connectionpool.py", line 392, in _make_request
    conn.request(method, url, **httplib_request_kw)
  File "D:\soft\python\lib\http\client.py", line 1230, in request
    self._send_request(method, url, body, headers, encode_chunked)
  File "D:\soft\python\lib\http\client.py", line 1276, in _send_request
    self.endheaders(body, encode_chunked=encode_chunked)
  File "D:\soft\python\lib\http\client.py", line 1225, in endheaders
    self._send_output(message_body, encode_chunked=encode_chunked)
  File "D:\soft\python\lib\http\client.py", line 1004, in _send_output
    self.send(msg)
  File "D:\soft\python\lib\http\client.py", line 944, in send
    self.connect()
  File "D:\soft\python\lib\site-packages\urllib3\connection.py", line 187, in connect
    conn = self._new_conn()
  File "D:\soft\python\lib\site-packages\urllib3\connection.py", line 171, in _new_conn
    raise NewConnectionError(
urllib3.exceptions.NewConnectionError: &lt;urllib3.connection.HTTPConnection object at 0x0000024C2ED2C880&gt;: Failed to establish a new connection: [Errno 11001] getaddrinfo failed

During handling of the above exception, another exception occurred:

Traceback (most recent call last):
  File "D:\soft\python\lib\site-packages\requests\adapters.py", line 439, in send
    resp = conn.urlopen(
  File "D:\soft\python\lib\site-packages\urllib3\connectionpool.py", line 724, in urlopen
    retries = retries.increment(
  File "D:\soft\python\lib\site-packages\urllib3\util\retry.py", line 439, in increment
    raise MaxRetryError(_pool, url, error or ResponseError(cause))
urllib3.exceptions.MaxRetryError: HTTPConnectionPool(host='ssssss', port=9101): Max retries exceeded with url: /api/auth/login (Caused by NewConnectionError('&lt;urllib3.connection.HTTPConnection object at 0x0000024C2ED2C880&gt;: Failed to establish a new connection: [Errno 11001] getaddrinfo failed'))

During handling of the above exception, another exception occurred:

Traceback (most recent call last):
  File "D:\python_test\libs\ddt.py", line 145, in wrapper
    return func(self, *args, **kwargs)
  File "D:\python_test\cases\test_01_login.py", line 40, in test_login
    res = self.do_request.send(url=new_url,  # url地址
  File "D:\python_test\scripts\handle_request.py", line 61, in send
    res = self.one_session.request(method, url, json=data, **kwargs)
  File "D:\soft\python\lib\site-packages\requests\sessions.py", line 530, in request
    resp = self.send(prep, **send_kwargs)
  File "D:\soft\python\lib\site-packages\requests\sessions.py", line 643, in send
    r = adapter.send(request, **kwargs)
  File "D:\soft\python\lib\site-packages\requests\adapters.py", line 516, in send
    raise ConnectionError(e, request=request)
requests.exceptions.ConnectionError: HTTPConnectionPool(host='ssssss', port=9101): Max retries exceeded with url: /api/auth/login (Caused by NewConnectionError('&lt;urllib3.connection.HTTPConnection object at 0x0000024C2ED2C880&gt;: Failed to establish a new connection: [Errno 11001] getaddrinfo failed'))


    </pre>
    </div>
    </td>
</tr>

<tr id='ft1_5' class='none'>
    <td class='errorCase'><div class='testcase'>test_login_5: 正常登录</div></td>
    <td colspan='5' align='center'>
    <!--默认收起错误信息 -Findyou
    <button id='btn_ft1_5' type="button"  class="btn btn-danger btn-xs collapsed" data-toggle="collapse" data-target='#div_ft1_5'>错误</button>
    <div id='div_ft1_5' class="collapse">  -->
    <!-- 默认展开错误信息 -Findyou -->
    <button id='btn_ft1_5' type="button"  class="btn btn-danger btn-xs" data-toggle="collapse" data-target='#div_ft1_5'>错误</button>
    <div id='div_ft1_5' class="collapse in" align="left">
    <pre>
    
ft1_5: http://ssssss:9101/api/auth/login
Traceback (most recent call last):
  File "D:\soft\python\lib\site-packages\urllib3\connection.py", line 159, in _new_conn
    conn = connection.create_connection(
  File "D:\soft\python\lib\site-packages\urllib3\util\connection.py", line 61, in create_connection
    for res in socket.getaddrinfo(host, port, family, socket.SOCK_STREAM):
  File "D:\soft\python\lib\socket.py", line 918, in getaddrinfo
    for res in _socket.getaddrinfo(host, port, family, type, proto, flags):
socket.gaierror: [Errno 11001] getaddrinfo failed

During handling of the above exception, another exception occurred:

Traceback (most recent call last):
  File "D:\soft\python\lib\site-packages\urllib3\connectionpool.py", line 670, in urlopen
    httplib_response = self._make_request(
  File "D:\soft\python\lib\site-packages\urllib3\connectionpool.py", line 392, in _make_request
    conn.request(method, url, **httplib_request_kw)
  File "D:\soft\python\lib\http\client.py", line 1230, in request
    self._send_request(method, url, body, headers, encode_chunked)
  File "D:\soft\python\lib\http\client.py", line 1276, in _send_request
    self.endheaders(body, encode_chunked=encode_chunked)
  File "D:\soft\python\lib\http\client.py", line 1225, in endheaders
    self._send_output(message_body, encode_chunked=encode_chunked)
  File "D:\soft\python\lib\http\client.py", line 1004, in _send_output
    self.send(msg)
  File "D:\soft\python\lib\http\client.py", line 944, in send
    self.connect()
  File "D:\soft\python\lib\site-packages\urllib3\connection.py", line 187, in connect
    conn = self._new_conn()
  File "D:\soft\python\lib\site-packages\urllib3\connection.py", line 171, in _new_conn
    raise NewConnectionError(
urllib3.exceptions.NewConnectionError: &lt;urllib3.connection.HTTPConnection object at 0x0000024C2ED2C7F0&gt;: Failed to establish a new connection: [Errno 11001] getaddrinfo failed

During handling of the above exception, another exception occurred:

Traceback (most recent call last):
  File "D:\soft\python\lib\site-packages\requests\adapters.py", line 439, in send
    resp = conn.urlopen(
  File "D:\soft\python\lib\site-packages\urllib3\connectionpool.py", line 724, in urlopen
    retries = retries.increment(
  File "D:\soft\python\lib\site-packages\urllib3\util\retry.py", line 439, in increment
    raise MaxRetryError(_pool, url, error or ResponseError(cause))
urllib3.exceptions.MaxRetryError: HTTPConnectionPool(host='ssssss', port=9101): Max retries exceeded with url: /api/auth/login (Caused by NewConnectionError('&lt;urllib3.connection.HTTPConnection object at 0x0000024C2ED2C7F0&gt;: Failed to establish a new connection: [Errno 11001] getaddrinfo failed'))

During handling of the above exception, another exception occurred:

Traceback (most recent call last):
  File "D:\python_test\libs\ddt.py", line 145, in wrapper
    return func(self, *args, **kwargs)
  File "D:\python_test\cases\test_01_login.py", line 40, in test_login
    res = self.do_request.send(url=new_url,  # url地址
  File "D:\python_test\scripts\handle_request.py", line 61, in send
    res = self.one_session.request(method, url, json=data, **kwargs)
  File "D:\soft\python\lib\site-packages\requests\sessions.py", line 530, in request
    resp = self.send(prep, **send_kwargs)
  File "D:\soft\python\lib\site-packages\requests\sessions.py", line 643, in send
    r = adapter.send(request, **kwargs)
  File "D:\soft\python\lib\site-packages\requests\adapters.py", line 516, in send
    raise ConnectionError(e, request=request)
requests.exceptions.ConnectionError: HTTPConnectionPool(host='ssssss', port=9101): Max retries exceeded with url: /api/auth/login (Caused by NewConnectionError('&lt;urllib3.connection.HTTPConnection object at 0x0000024C2ED2C7F0&gt;: Failed to establish a new connection: [Errno 11001] getaddrinfo failed'))


    </pre>
    </div>
    </td>
</tr>

<tr id='ft1_6' class='none'>
    <td class='errorCase'><div class='testcase'>test_login_6: 手机号码输入特殊字符</div></td>
    <td colspan='5' align='center'>
    <!--默认收起错误信息 -Findyou
    <button id='btn_ft1_6' type="button"  class="btn btn-danger btn-xs collapsed" data-toggle="collapse" data-target='#div_ft1_6'>错误</button>
    <div id='div_ft1_6' class="collapse">  -->
    <!-- 默认展开错误信息 -Findyou -->
    <button id='btn_ft1_6' type="button"  class="btn btn-danger btn-xs" data-toggle="collapse" data-target='#div_ft1_6'>错误</button>
    <div id='div_ft1_6' class="collapse in" align="left">
    <pre>
    
ft1_6: http://ssssss:9101/api/auth/login
Traceback (most recent call last):
  File "D:\soft\python\lib\site-packages\urllib3\connection.py", line 159, in _new_conn
    conn = connection.create_connection(
  File "D:\soft\python\lib\site-packages\urllib3\util\connection.py", line 61, in create_connection
    for res in socket.getaddrinfo(host, port, family, socket.SOCK_STREAM):
  File "D:\soft\python\lib\socket.py", line 918, in getaddrinfo
    for res in _socket.getaddrinfo(host, port, family, type, proto, flags):
socket.gaierror: [Errno 11001] getaddrinfo failed

During handling of the above exception, another exception occurred:

Traceback (most recent call last):
  File "D:\soft\python\lib\site-packages\urllib3\connectionpool.py", line 670, in urlopen
    httplib_response = self._make_request(
  File "D:\soft\python\lib\site-packages\urllib3\connectionpool.py", line 392, in _make_request
    conn.request(method, url, **httplib_request_kw)
  File "D:\soft\python\lib\http\client.py", line 1230, in request
    self._send_request(method, url, body, headers, encode_chunked)
  File "D:\soft\python\lib\http\client.py", line 1276, in _send_request
    self.endheaders(body, encode_chunked=encode_chunked)
  File "D:\soft\python\lib\http\client.py", line 1225, in endheaders
    self._send_output(message_body, encode_chunked=encode_chunked)
  File "D:\soft\python\lib\http\client.py", line 1004, in _send_output
    self.send(msg)
  File "D:\soft\python\lib\http\client.py", line 944, in send
    self.connect()
  File "D:\soft\python\lib\site-packages\urllib3\connection.py", line 187, in connect
    conn = self._new_conn()
  File "D:\soft\python\lib\site-packages\urllib3\connection.py", line 171, in _new_conn
    raise NewConnectionError(
urllib3.exceptions.NewConnectionError: &lt;urllib3.connection.HTTPConnection object at 0x0000024C2ED2C880&gt;: Failed to establish a new connection: [Errno 11001] getaddrinfo failed

During handling of the above exception, another exception occurred:

Traceback (most recent call last):
  File "D:\soft\python\lib\site-packages\requests\adapters.py", line 439, in send
    resp = conn.urlopen(
  File "D:\soft\python\lib\site-packages\urllib3\connectionpool.py", line 724, in urlopen
    retries = retries.increment(
  File "D:\soft\python\lib\site-packages\urllib3\util\retry.py", line 439, in increment
    raise MaxRetryError(_pool, url, error or ResponseError(cause))
urllib3.exceptions.MaxRetryError: HTTPConnectionPool(host='ssssss', port=9101): Max retries exceeded with url: /api/auth/login (Caused by NewConnectionError('&lt;urllib3.connection.HTTPConnection object at 0x0000024C2ED2C880&gt;: Failed to establish a new connection: [Errno 11001] getaddrinfo failed'))

During handling of the above exception, another exception occurred:

Traceback (most recent call last):
  File "D:\python_test\libs\ddt.py", line 145, in wrapper
    return func(self, *args, **kwargs)
  File "D:\python_test\cases\test_01_login.py", line 40, in test_login
    res = self.do_request.send(url=new_url,  # url地址
  File "D:\python_test\scripts\handle_request.py", line 61, in send
    res = self.one_session.request(method, url, json=data, **kwargs)
  File "D:\soft\python\lib\site-packages\requests\sessions.py", line 530, in request
    resp = self.send(prep, **send_kwargs)
  File "D:\soft\python\lib\site-packages\requests\sessions.py", line 643, in send
    r = adapter.send(request, **kwargs)
  File "D:\soft\python\lib\site-packages\requests\adapters.py", line 516, in send
    raise ConnectionError(e, request=request)
requests.exceptions.ConnectionError: HTTPConnectionPool(host='ssssss', port=9101): Max retries exceeded with url: /api/auth/login (Caused by NewConnectionError('&lt;urllib3.connection.HTTPConnection object at 0x0000024C2ED2C880&gt;: Failed to establish a new connection: [Errno 11001] getaddrinfo failed'))


    </pre>
    </div>
    </td>
</tr>

<tr class='errorClass warning'>
    <td>test_02_product.TestProduct</td>
    <td class="text-center">4</td>
    <td class="text-center">0</td>
    <td class="text-center">0</td>
    <td class="text-center">4</td>
    <td class="text-center"><a href="javascript:showClassDetail('c2',4)" class="detail" id='c2'>详细</a></td>
</tr>

<tr id='ft2_1' class='none'>
    <td class='errorCase'><div class='testcase'>test_product_1: 正常登录</div></td>
    <td colspan='5' align='center'>
    <!--默认收起错误信息 -Findyou
    <button id='btn_ft2_1' type="button"  class="btn btn-danger btn-xs collapsed" data-toggle="collapse" data-target='#div_ft2_1'>错误</button>
    <div id='div_ft2_1' class="collapse">  -->
    <!-- 默认展开错误信息 -Findyou -->
    <button id='btn_ft2_1' type="button"  class="btn btn-danger btn-xs" data-toggle="collapse" data-target='#div_ft2_1'>错误</button>
    <div id='div_ft2_1' class="collapse in" align="left">
    <pre>
    
ft2_1: Traceback (most recent call last):
  File "D:\soft\python\lib\site-packages\urllib3\connection.py", line 159, in _new_conn
    conn = connection.create_connection(
  File "D:\soft\python\lib\site-packages\urllib3\util\connection.py", line 61, in create_connection
    for res in socket.getaddrinfo(host, port, family, socket.SOCK_STREAM):
  File "D:\soft\python\lib\socket.py", line 918, in getaddrinfo
    for res in _socket.getaddrinfo(host, port, family, type, proto, flags):
socket.gaierror: [Errno 11001] getaddrinfo failed

During handling of the above exception, another exception occurred:

Traceback (most recent call last):
  File "D:\soft\python\lib\site-packages\urllib3\connectionpool.py", line 670, in urlopen
    httplib_response = self._make_request(
  File "D:\soft\python\lib\site-packages\urllib3\connectionpool.py", line 392, in _make_request
    conn.request(method, url, **httplib_request_kw)
  File "D:\soft\python\lib\http\client.py", line 1230, in request
    self._send_request(method, url, body, headers, encode_chunked)
  File "D:\soft\python\lib\http\client.py", line 1276, in _send_request
    self.endheaders(body, encode_chunked=encode_chunked)
  File "D:\soft\python\lib\http\client.py", line 1225, in endheaders
    self._send_output(message_body, encode_chunked=encode_chunked)
  File "D:\soft\python\lib\http\client.py", line 1004, in _send_output
    self.send(msg)
  File "D:\soft\python\lib\http\client.py", line 944, in send
    self.connect()
  File "D:\soft\python\lib\site-packages\urllib3\connection.py", line 187, in connect
    conn = self._new_conn()
  File "D:\soft\python\lib\site-packages\urllib3\connection.py", line 171, in _new_conn
    raise NewConnectionError(
urllib3.exceptions.NewConnectionError: &lt;urllib3.connection.HTTPConnection object at 0x0000024C2F64C460&gt;: Failed to establish a new connection: [Errno 11001] getaddrinfo failed

During handling of the above exception, another exception occurred:

Traceback (most recent call last):
  File "D:\soft\python\lib\site-packages\requests\adapters.py", line 439, in send
    resp = conn.urlopen(
  File "D:\soft\python\lib\site-packages\urllib3\connectionpool.py", line 724, in urlopen
    retries = retries.increment(
  File "D:\soft\python\lib\site-packages\urllib3\util\retry.py", line 439, in increment
    raise MaxRetryError(_pool, url, error or ResponseError(cause))
urllib3.exceptions.MaxRetryError: HTTPConnectionPool(host='ssssss', port=9101): Max retries exceeded with url: /api/auth/login (Caused by NewConnectionError('&lt;urllib3.connection.HTTPConnection object at 0x0000024C2F64C460&gt;: Failed to establish a new connection: [Errno 11001] getaddrinfo failed'))

During handling of the above exception, another exception occurred:

Traceback (most recent call last):
  File "D:\python_test\libs\ddt.py", line 145, in wrapper
    return func(self, *args, **kwargs)
  File "D:\python_test\cases\test_02_product.py", line 46, in test_product
    res = self.do_request.send(url=new_url,  # url地址
  File "D:\python_test\scripts\handle_request.py", line 61, in send
    res = self.one_session.request(method, url, json=data, **kwargs)
  File "D:\soft\python\lib\site-packages\requests\sessions.py", line 530, in request
    resp = self.send(prep, **send_kwargs)
  File "D:\soft\python\lib\site-packages\requests\sessions.py", line 643, in send
    r = adapter.send(request, **kwargs)
  File "D:\soft\python\lib\site-packages\requests\adapters.py", line 516, in send
    raise ConnectionError(e, request=request)
requests.exceptions.ConnectionError: HTTPConnectionPool(host='ssssss', port=9101): Max retries exceeded with url: /api/auth/login (Caused by NewConnectionError('&lt;urllib3.connection.HTTPConnection object at 0x0000024C2F64C460&gt;: Failed to establish a new connection: [Errno 11001] getaddrinfo failed'))


    </pre>
    </div>
    </td>
</tr>

<tr id='ft2_2' class='none'>
    <td class='errorCase'><div class='testcase'>test_product_2: 添加产品为草稿模式</div></td>
    <td colspan='5' align='center'>
    <!--默认收起错误信息 -Findyou
    <button id='btn_ft2_2' type="button"  class="btn btn-danger btn-xs collapsed" data-toggle="collapse" data-target='#div_ft2_2'>错误</button>
    <div id='div_ft2_2' class="collapse">  -->
    <!-- 默认展开错误信息 -Findyou -->
    <button id='btn_ft2_2' type="button"  class="btn btn-danger btn-xs" data-toggle="collapse" data-target='#div_ft2_2'>错误</button>
    <div id='div_ft2_2' class="collapse in" align="left">
    <pre>
    
ft2_2: Traceback (most recent call last):
  File "D:\soft\python\lib\site-packages\urllib3\connection.py", line 159, in _new_conn
    conn = connection.create_connection(
  File "D:\soft\python\lib\site-packages\urllib3\util\connection.py", line 61, in create_connection
    for res in socket.getaddrinfo(host, port, family, socket.SOCK_STREAM):
  File "D:\soft\python\lib\socket.py", line 918, in getaddrinfo
    for res in _socket.getaddrinfo(host, port, family, type, proto, flags):
socket.gaierror: [Errno 11001] getaddrinfo failed

During handling of the above exception, another exception occurred:

Traceback (most recent call last):
  File "D:\soft\python\lib\site-packages\urllib3\connectionpool.py", line 670, in urlopen
    httplib_response = self._make_request(
  File "D:\soft\python\lib\site-packages\urllib3\connectionpool.py", line 392, in _make_request
    conn.request(method, url, **httplib_request_kw)
  File "D:\soft\python\lib\http\client.py", line 1230, in request
    self._send_request(method, url, body, headers, encode_chunked)
  File "D:\soft\python\lib\http\client.py", line 1276, in _send_request
    self.endheaders(body, encode_chunked=encode_chunked)
  File "D:\soft\python\lib\http\client.py", line 1225, in endheaders
    self._send_output(message_body, encode_chunked=encode_chunked)
  File "D:\soft\python\lib\http\client.py", line 1004, in _send_output
    self.send(msg)
  File "D:\soft\python\lib\http\client.py", line 944, in send
    self.connect()
  File "D:\soft\python\lib\site-packages\urllib3\connection.py", line 187, in connect
    conn = self._new_conn()
  File "D:\soft\python\lib\site-packages\urllib3\connection.py", line 171, in _new_conn
    raise NewConnectionError(
urllib3.exceptions.NewConnectionError: &lt;urllib3.connection.HTTPConnection object at 0x0000024C2F64C460&gt;: Failed to establish a new connection: [Errno 11001] getaddrinfo failed

During handling of the above exception, another exception occurred:

Traceback (most recent call last):
  File "D:\soft\python\lib\site-packages\requests\adapters.py", line 439, in send
    resp = conn.urlopen(
  File "D:\soft\python\lib\site-packages\urllib3\connectionpool.py", line 724, in urlopen
    retries = retries.increment(
  File "D:\soft\python\lib\site-packages\urllib3\util\retry.py", line 439, in increment
    raise MaxRetryError(_pool, url, error or ResponseError(cause))
urllib3.exceptions.MaxRetryError: HTTPConnectionPool(host='ssssss', port=9101): Max retries exceeded with url: /api/product/busproduct/goods (Caused by NewConnectionError('&lt;urllib3.connection.HTTPConnection object at 0x0000024C2F64C460&gt;: Failed to establish a new connection: [Errno 11001] getaddrinfo failed'))

During handling of the above exception, another exception occurred:

Traceback (most recent call last):
  File "D:\python_test\libs\ddt.py", line 145, in wrapper
    return func(self, *args, **kwargs)
  File "D:\python_test\cases\test_02_product.py", line 46, in test_product
    res = self.do_request.send(url=new_url,  # url地址
  File "D:\python_test\scripts\handle_request.py", line 61, in send
    res = self.one_session.request(method, url, json=data, **kwargs)
  File "D:\soft\python\lib\site-packages\requests\sessions.py", line 530, in request
    resp = self.send(prep, **send_kwargs)
  File "D:\soft\python\lib\site-packages\requests\sessions.py", line 643, in send
    r = adapter.send(request, **kwargs)
  File "D:\soft\python\lib\site-packages\requests\adapters.py", line 516, in send
    raise ConnectionError(e, request=request)
requests.exceptions.ConnectionError: HTTPConnectionPool(host='ssssss', port=9101): Max retries exceeded with url: /api/product/busproduct/goods (Caused by NewConnectionError('&lt;urllib3.connection.HTTPConnection object at 0x0000024C2F64C460&gt;: Failed to establish a new connection: [Errno 11001] getaddrinfo failed'))


    </pre>
    </div>
    </td>
</tr>

<tr id='ft2_3' class='none'>
    <td class='errorCase'><div class='testcase'>test_product_3: 获取列表</div></td>
    <td colspan='5' align='center'>
    <!--默认收起错误信息 -Findyou
    <button id='btn_ft2_3' type="button"  class="btn btn-danger btn-xs collapsed" data-toggle="collapse" data-target='#div_ft2_3'>错误</button>
    <div id='div_ft2_3' class="collapse">  -->
    <!-- 默认展开错误信息 -Findyou -->
    <button id='btn_ft2_3' type="button"  class="btn btn-danger btn-xs" data-toggle="collapse" data-target='#div_ft2_3'>错误</button>
    <div id='div_ft2_3' class="collapse in" align="left">
    <pre>
    
ft2_3: Traceback (most recent call last):
  File "D:\soft\python\lib\site-packages\urllib3\connection.py", line 159, in _new_conn
    conn = connection.create_connection(
  File "D:\soft\python\lib\site-packages\urllib3\util\connection.py", line 61, in create_connection
    for res in socket.getaddrinfo(host, port, family, socket.SOCK_STREAM):
  File "D:\soft\python\lib\socket.py", line 918, in getaddrinfo
    for res in _socket.getaddrinfo(host, port, family, type, proto, flags):
socket.gaierror: [Errno 11001] getaddrinfo failed

During handling of the above exception, another exception occurred:

Traceback (most recent call last):
  File "D:\soft\python\lib\site-packages\urllib3\connectionpool.py", line 670, in urlopen
    httplib_response = self._make_request(
  File "D:\soft\python\lib\site-packages\urllib3\connectionpool.py", line 392, in _make_request
    conn.request(method, url, **httplib_request_kw)
  File "D:\soft\python\lib\http\client.py", line 1230, in request
    self._send_request(method, url, body, headers, encode_chunked)
  File "D:\soft\python\lib\http\client.py", line 1276, in _send_request
    self.endheaders(body, encode_chunked=encode_chunked)
  File "D:\soft\python\lib\http\client.py", line 1225, in endheaders
    self._send_output(message_body, encode_chunked=encode_chunked)
  File "D:\soft\python\lib\http\client.py", line 1004, in _send_output
    self.send(msg)
  File "D:\soft\python\lib\http\client.py", line 944, in send
    self.connect()
  File "D:\soft\python\lib\site-packages\urllib3\connection.py", line 187, in connect
    conn = self._new_conn()
  File "D:\soft\python\lib\site-packages\urllib3\connection.py", line 171, in _new_conn
    raise NewConnectionError(
urllib3.exceptions.NewConnectionError: &lt;urllib3.connection.HTTPConnection object at 0x0000024C2F64C400&gt;: Failed to establish a new connection: [Errno 11001] getaddrinfo failed

During handling of the above exception, another exception occurred:

Traceback (most recent call last):
  File "D:\soft\python\lib\site-packages\requests\adapters.py", line 439, in send
    resp = conn.urlopen(
  File "D:\soft\python\lib\site-packages\urllib3\connectionpool.py", line 724, in urlopen
    retries = retries.increment(
  File "D:\soft\python\lib\site-packages\urllib3\util\retry.py", line 439, in increment
    raise MaxRetryError(_pool, url, error or ResponseError(cause))
urllib3.exceptions.MaxRetryError: HTTPConnectionPool(host='ssssss', port=9101): Max retries exceeded with url: /api/product/busproduct/list?page=1&amp;perPage=20&amp;page=1&amp;perPage=20 (Caused by NewConnectionError('&lt;urllib3.connection.HTTPConnection object at 0x0000024C2F64C400&gt;: Failed to establish a new connection: [Errno 11001] getaddrinfo failed'))

During handling of the above exception, another exception occurred:

Traceback (most recent call last):
  File "D:\python_test\libs\ddt.py", line 145, in wrapper
    return func(self, *args, **kwargs)
  File "D:\python_test\cases\test_02_product.py", line 46, in test_product
    res = self.do_request.send(url=new_url,  # url地址
  File "D:\python_test\scripts\handle_request.py", line 57, in send
    res = self.one_session.request(method, url, params=data, **kwargs)
  File "D:\soft\python\lib\site-packages\requests\sessions.py", line 530, in request
    resp = self.send(prep, **send_kwargs)
  File "D:\soft\python\lib\site-packages\requests\sessions.py", line 643, in send
    r = adapter.send(request, **kwargs)
  File "D:\soft\python\lib\site-packages\requests\adapters.py", line 516, in send
    raise ConnectionError(e, request=request)
requests.exceptions.ConnectionError: HTTPConnectionPool(host='ssssss', port=9101): Max retries exceeded with url: /api/product/busproduct/list?page=1&amp;perPage=20&amp;page=1&amp;perPage=20 (Caused by NewConnectionError('&lt;urllib3.connection.HTTPConnection object at 0x0000024C2F64C400&gt;: Failed to establish a new connection: [Errno 11001] getaddrinfo failed'))


    </pre>
    </div>
    </td>
</tr>

<tr id='ft2_4' class='none'>
    <td class='errorCase'><div class='testcase'>test_product_4: 删除产品</div></td>
    <td colspan='5' align='center'>
    <!--默认收起错误信息 -Findyou
    <button id='btn_ft2_4' type="button"  class="btn btn-danger btn-xs collapsed" data-toggle="collapse" data-target='#div_ft2_4'>错误</button>
    <div id='div_ft2_4' class="collapse">  -->
    <!-- 默认展开错误信息 -Findyou -->
    <button id='btn_ft2_4' type="button"  class="btn btn-danger btn-xs" data-toggle="collapse" data-target='#div_ft2_4'>错误</button>
    <div id='div_ft2_4' class="collapse in" align="left">
    <pre>
    
ft2_4: 1396740097277169664
Traceback (most recent call last):
  File "D:\soft\python\lib\site-packages\urllib3\connection.py", line 159, in _new_conn
    conn = connection.create_connection(
  File "D:\soft\python\lib\site-packages\urllib3\util\connection.py", line 61, in create_connection
    for res in socket.getaddrinfo(host, port, family, socket.SOCK_STREAM):
  File "D:\soft\python\lib\socket.py", line 918, in getaddrinfo
    for res in _socket.getaddrinfo(host, port, family, type, proto, flags):
socket.gaierror: [Errno 11001] getaddrinfo failed

During handling of the above exception, another exception occurred:

Traceback (most recent call last):
  File "D:\soft\python\lib\site-packages\urllib3\connectionpool.py", line 670, in urlopen
    httplib_response = self._make_request(
  File "D:\soft\python\lib\site-packages\urllib3\connectionpool.py", line 392, in _make_request
    conn.request(method, url, **httplib_request_kw)
  File "D:\soft\python\lib\http\client.py", line 1230, in request
    self._send_request(method, url, body, headers, encode_chunked)
  File "D:\soft\python\lib\http\client.py", line 1276, in _send_request
    self.endheaders(body, encode_chunked=encode_chunked)
  File "D:\soft\python\lib\http\client.py", line 1225, in endheaders
    self._send_output(message_body, encode_chunked=encode_chunked)
  File "D:\soft\python\lib\http\client.py", line 1004, in _send_output
    self.send(msg)
  File "D:\soft\python\lib\http\client.py", line 944, in send
    self.connect()
  File "D:\soft\python\lib\site-packages\urllib3\connection.py", line 187, in connect
    conn = self._new_conn()
  File "D:\soft\python\lib\site-packages\urllib3\connection.py", line 171, in _new_conn
    raise NewConnectionError(
urllib3.exceptions.NewConnectionError: &lt;urllib3.connection.HTTPConnection object at 0x0000024C2F6FF130&gt;: Failed to establish a new connection: [Errno 11001] getaddrinfo failed

During handling of the above exception, another exception occurred:

Traceback (most recent call last):
  File "D:\soft\python\lib\site-packages\requests\adapters.py", line 439, in send
    resp = conn.urlopen(
  File "D:\soft\python\lib\site-packages\urllib3\connectionpool.py", line 724, in urlopen
    retries = retries.increment(
  File "D:\soft\python\lib\site-packages\urllib3\util\retry.py", line 439, in increment
    raise MaxRetryError(_pool, url, error or ResponseError(cause))
urllib3.exceptions.MaxRetryError: HTTPConnectionPool(host='ssssss', port=9101): Max retries exceeded with url: /api/product/busproduct/goods/1396740097277169664 (Caused by NewConnectionError('&lt;urllib3.connection.HTTPConnection object at 0x0000024C2F6FF130&gt;: Failed to establish a new connection: [Errno 11001] getaddrinfo failed'))

During handling of the above exception, another exception occurred:

Traceback (most recent call last):
  File "D:\python_test\libs\ddt.py", line 145, in wrapper
    return func(self, *args, **kwargs)
  File "D:\python_test\cases\test_02_product.py", line 46, in test_product
    res = self.do_request.send(url=new_url,  # url地址
  File "D:\python_test\scripts\handle_request.py", line 61, in send
    res = self.one_session.request(method, url, json=data, **kwargs)
  File "D:\soft\python\lib\site-packages\requests\sessions.py", line 530, in request
    resp = self.send(prep, **send_kwargs)
  File "D:\soft\python\lib\site-packages\requests\sessions.py", line 643, in send
    r = adapter.send(request, **kwargs)
  File "D:\soft\python\lib\site-packages\requests\adapters.py", line 516, in send
    raise ConnectionError(e, request=request)
requests.exceptions.ConnectionError: HTTPConnectionPool(host='ssssss', port=9101): Max retries exceeded with url: /api/product/busproduct/goods/1396740097277169664 (Caused by NewConnectionError('&lt;urllib3.connection.HTTPConnection object at 0x0000024C2F6FF130&gt;: Failed to establish a new connection: [Errno 11001] getaddrinfo failed'))


    </pre>
    </div>
    </td>
</tr>

<tr class='errorClass warning'>
    <td>test_03_company.TestCompany</td>
    <td class="text-center">12</td>
    <td class="text-center">0</td>
    <td class="text-center">0</td>
    <td class="text-center">12</td>
    <td class="text-center"><a href="javascript:showClassDetail('c3',12)" class="detail" id='c3'>详细</a></td>
</tr>

<tr id='ft3_1' class='none'>
    <td class='errorCase'><div class='testcase'>test_company_01: 正常登录</div></td>
    <td colspan='5' align='center'>
    <!--默认收起错误信息 -Findyou
    <button id='btn_ft3_1' type="button"  class="btn btn-danger btn-xs collapsed" data-toggle="collapse" data-target='#div_ft3_1'>错误</button>
    <div id='div_ft3_1' class="collapse">  -->
    <!-- 默认展开错误信息 -Findyou -->
    <button id='btn_ft3_1' type="button"  class="btn btn-danger btn-xs" data-toggle="collapse" data-target='#div_ft3_1'>错误</button>
    <div id='div_ft3_1' class="collapse in" align="left">
    <pre>
    
ft3_1: Traceback (most recent call last):
  File "D:\soft\python\lib\site-packages\urllib3\connection.py", line 159, in _new_conn
    conn = connection.create_connection(
  File "D:\soft\python\lib\site-packages\urllib3\util\connection.py", line 61, in create_connection
    for res in socket.getaddrinfo(host, port, family, socket.SOCK_STREAM):
  File "D:\soft\python\lib\socket.py", line 918, in getaddrinfo
    for res in _socket.getaddrinfo(host, port, family, type, proto, flags):
socket.gaierror: [Errno 11001] getaddrinfo failed

During handling of the above exception, another exception occurred:

Traceback (most recent call last):
  File "D:\soft\python\lib\site-packages\urllib3\connectionpool.py", line 670, in urlopen
    httplib_response = self._make_request(
  File "D:\soft\python\lib\site-packages\urllib3\connectionpool.py", line 392, in _make_request
    conn.request(method, url, **httplib_request_kw)
  File "D:\soft\python\lib\http\client.py", line 1230, in request
    self._send_request(method, url, body, headers, encode_chunked)
  File "D:\soft\python\lib\http\client.py", line 1276, in _send_request
    self.endheaders(body, encode_chunked=encode_chunked)
  File "D:\soft\python\lib\http\client.py", line 1225, in endheaders
    self._send_output(message_body, encode_chunked=encode_chunked)
  File "D:\soft\python\lib\http\client.py", line 1004, in _send_output
    self.send(msg)
  File "D:\soft\python\lib\http\client.py", line 944, in send
    self.connect()
  File "D:\soft\python\lib\site-packages\urllib3\connection.py", line 187, in connect
    conn = self._new_conn()
  File "D:\soft\python\lib\site-packages\urllib3\connection.py", line 171, in _new_conn
    raise NewConnectionError(
urllib3.exceptions.NewConnectionError: &lt;urllib3.connection.HTTPConnection object at 0x0000024C2F6FF2B0&gt;: Failed to establish a new connection: [Errno 11001] getaddrinfo failed

During handling of the above exception, another exception occurred:

Traceback (most recent call last):
  File "D:\soft\python\lib\site-packages\requests\adapters.py", line 439, in send
    resp = conn.urlopen(
  File "D:\soft\python\lib\site-packages\urllib3\connectionpool.py", line 724, in urlopen
    retries = retries.increment(
  File "D:\soft\python\lib\site-packages\urllib3\util\retry.py", line 439, in increment
    raise MaxRetryError(_pool, url, error or ResponseError(cause))
urllib3.exceptions.MaxRetryError: HTTPConnectionPool(host='ssssss', port=9101): Max retries exceeded with url: /api/auth/login (Caused by NewConnectionError('&lt;urllib3.connection.HTTPConnection object at 0x0000024C2F6FF2B0&gt;: Failed to establish a new connection: [Errno 11001] getaddrinfo failed'))

During handling of the above exception, another exception occurred:

Traceback (most recent call last):
  File "D:\python_test\libs\ddt.py", line 145, in wrapper
    return func(self, *args, **kwargs)
  File "D:\python_test\cases\test_03_company.py", line 43, in test_company
    res = self.do_request.send(url=new_url,  # url地址
  File "D:\python_test\scripts\handle_request.py", line 61, in send
    res = self.one_session.request(method, url, json=data, **kwargs)
  File "D:\soft\python\lib\site-packages\requests\sessions.py", line 530, in request
    resp = self.send(prep, **send_kwargs)
  File "D:\soft\python\lib\site-packages\requests\sessions.py", line 643, in send
    r = adapter.send(request, **kwargs)
  File "D:\soft\python\lib\site-packages\requests\adapters.py", line 516, in send
    raise ConnectionError(e, request=request)
requests.exceptions.ConnectionError: HTTPConnectionPool(host='ssssss', port=9101): Max retries exceeded with url: /api/auth/login (Caused by NewConnectionError('&lt;urllib3.connection.HTTPConnection object at 0x0000024C2F6FF2B0&gt;: Failed to establish a new connection: [Errno 11001] getaddrinfo failed'))


    </pre>
    </div>
    </td>
</tr>

<tr id='ft3_2' class='none'>
    <td class='errorCase'><div class='testcase'>test_company_02: 获取用户信息</div></td>
    <td colspan='5' align='center'>
    <!--默认收起错误信息 -Findyou
    <button id='btn_ft3_2' type="button"  class="btn btn-danger btn-xs collapsed" data-toggle="collapse" data-target='#div_ft3_2'>错误</button>
    <div id='div_ft3_2' class="collapse">  -->
    <!-- 默认展开错误信息 -Findyou -->
    <button id='btn_ft3_2' type="button"  class="btn btn-danger btn-xs" data-toggle="collapse" data-target='#div_ft3_2'>错误</button>
    <div id='div_ft3_2' class="collapse in" align="left">
    <pre>
    
ft3_2: Traceback (most recent call last):
  File "D:\soft\python\lib\site-packages\urllib3\connection.py", line 159, in _new_conn
    conn = connection.create_connection(
  File "D:\soft\python\lib\site-packages\urllib3\util\connection.py", line 61, in create_connection
    for res in socket.getaddrinfo(host, port, family, socket.SOCK_STREAM):
  File "D:\soft\python\lib\socket.py", line 918, in getaddrinfo
    for res in _socket.getaddrinfo(host, port, family, type, proto, flags):
socket.gaierror: [Errno 11001] getaddrinfo failed

During handling of the above exception, another exception occurred:

Traceback (most recent call last):
  File "D:\soft\python\lib\site-packages\urllib3\connectionpool.py", line 670, in urlopen
    httplib_response = self._make_request(
  File "D:\soft\python\lib\site-packages\urllib3\connectionpool.py", line 392, in _make_request
    conn.request(method, url, **httplib_request_kw)
  File "D:\soft\python\lib\http\client.py", line 1230, in request
    self._send_request(method, url, body, headers, encode_chunked)
  File "D:\soft\python\lib\http\client.py", line 1276, in _send_request
    self.endheaders(body, encode_chunked=encode_chunked)
  File "D:\soft\python\lib\http\client.py", line 1225, in endheaders
    self._send_output(message_body, encode_chunked=encode_chunked)
  File "D:\soft\python\lib\http\client.py", line 1004, in _send_output
    self.send(msg)
  File "D:\soft\python\lib\http\client.py", line 944, in send
    self.connect()
  File "D:\soft\python\lib\site-packages\urllib3\connection.py", line 187, in connect
    conn = self._new_conn()
  File "D:\soft\python\lib\site-packages\urllib3\connection.py", line 171, in _new_conn
    raise NewConnectionError(
urllib3.exceptions.NewConnectionError: &lt;urllib3.connection.HTTPConnection object at 0x0000024C2F6FF2B0&gt;: Failed to establish a new connection: [Errno 11001] getaddrinfo failed

During handling of the above exception, another exception occurred:

Traceback (most recent call last):
  File "D:\soft\python\lib\site-packages\requests\adapters.py", line 439, in send
    resp = conn.urlopen(
  File "D:\soft\python\lib\site-packages\urllib3\connectionpool.py", line 724, in urlopen
    retries = retries.increment(
  File "D:\soft\python\lib\site-packages\urllib3\util\retry.py", line 439, in increment
    raise MaxRetryError(_pool, url, error or ResponseError(cause))
urllib3.exceptions.MaxRetryError: HTTPConnectionPool(host='ssssss', port=9101): Max retries exceeded with url: /api/admin/user/info/0 (Caused by NewConnectionError('&lt;urllib3.connection.HTTPConnection object at 0x0000024C2F6FF2B0&gt;: Failed to establish a new connection: [Errno 11001] getaddrinfo failed'))

During handling of the above exception, another exception occurred:

Traceback (most recent call last):
  File "D:\python_test\libs\ddt.py", line 145, in wrapper
    return func(self, *args, **kwargs)
  File "D:\python_test\cases\test_03_company.py", line 43, in test_company
    res = self.do_request.send(url=new_url,  # url地址
  File "D:\python_test\scripts\handle_request.py", line 57, in send
    res = self.one_session.request(method, url, params=data, **kwargs)
  File "D:\soft\python\lib\site-packages\requests\sessions.py", line 530, in request
    resp = self.send(prep, **send_kwargs)
  File "D:\soft\python\lib\site-packages\requests\sessions.py", line 643, in send
    r = adapter.send(request, **kwargs)
  File "D:\soft\python\lib\site-packages\requests\adapters.py", line 516, in send
    raise ConnectionError(e, request=request)
requests.exceptions.ConnectionError: HTTPConnectionPool(host='ssssss', port=9101): Max retries exceeded with url: /api/admin/user/info/0 (Caused by NewConnectionError('&lt;urllib3.connection.HTTPConnection object at 0x0000024C2F6FF2B0&gt;: Failed to establish a new connection: [Errno 11001] getaddrinfo failed'))


    </pre>
    </div>
    </td>
</tr>

<tr id='ft3_3' class='none'>
    <td class='errorCase'><div class='testcase'>test_company_03: 获取公司信息</div></td>
    <td colspan='5' align='center'>
    <!--默认收起错误信息 -Findyou
    <button id='btn_ft3_3' type="button"  class="btn btn-danger btn-xs collapsed" data-toggle="collapse" data-target='#div_ft3_3'>错误</button>
    <div id='div_ft3_3' class="collapse">  -->
    <!-- 默认展开错误信息 -Findyou -->
    <button id='btn_ft3_3' type="button"  class="btn btn-danger btn-xs" data-toggle="collapse" data-target='#div_ft3_3'>错误</button>
    <div id='div_ft3_3' class="collapse in" align="left">
    <pre>
    
ft3_3: Traceback (most recent call last):
  File "D:\soft\python\lib\site-packages\urllib3\connection.py", line 159, in _new_conn
    conn = connection.create_connection(
  File "D:\soft\python\lib\site-packages\urllib3\util\connection.py", line 61, in create_connection
    for res in socket.getaddrinfo(host, port, family, socket.SOCK_STREAM):
  File "D:\soft\python\lib\socket.py", line 918, in getaddrinfo
    for res in _socket.getaddrinfo(host, port, family, type, proto, flags):
socket.gaierror: [Errno 11001] getaddrinfo failed

During handling of the above exception, another exception occurred:

Traceback (most recent call last):
  File "D:\soft\python\lib\site-packages\urllib3\connectionpool.py", line 670, in urlopen
    httplib_response = self._make_request(
  File "D:\soft\python\lib\site-packages\urllib3\connectionpool.py", line 392, in _make_request
    conn.request(method, url, **httplib_request_kw)
  File "D:\soft\python\lib\http\client.py", line 1230, in request
    self._send_request(method, url, body, headers, encode_chunked)
  File "D:\soft\python\lib\http\client.py", line 1276, in _send_request
    self.endheaders(body, encode_chunked=encode_chunked)
  File "D:\soft\python\lib\http\client.py", line 1225, in endheaders
    self._send_output(message_body, encode_chunked=encode_chunked)
  File "D:\soft\python\lib\http\client.py", line 1004, in _send_output
    self.send(msg)
  File "D:\soft\python\lib\http\client.py", line 944, in send
    self.connect()
  File "D:\soft\python\lib\site-packages\urllib3\connection.py", line 187, in connect
    conn = self._new_conn()
  File "D:\soft\python\lib\site-packages\urllib3\connection.py", line 171, in _new_conn
    raise NewConnectionError(
urllib3.exceptions.NewConnectionError: &lt;urllib3.connection.HTTPConnection object at 0x0000024C2F6FF3A0&gt;: Failed to establish a new connection: [Errno 11001] getaddrinfo failed

During handling of the above exception, another exception occurred:

Traceback (most recent call last):
  File "D:\soft\python\lib\site-packages\requests\adapters.py", line 439, in send
    resp = conn.urlopen(
  File "D:\soft\python\lib\site-packages\urllib3\connectionpool.py", line 724, in urlopen
    retries = retries.increment(
  File "D:\soft\python\lib\site-packages\urllib3\util\retry.py", line 439, in increment
    raise MaxRetryError(_pool, url, error or ResponseError(cause))
urllib3.exceptions.MaxRetryError: HTTPConnectionPool(host='ssssss', port=9101): Max retries exceeded with url: /api/admin/buscompany/subcompany (Caused by NewConnectionError('&lt;urllib3.connection.HTTPConnection object at 0x0000024C2F6FF3A0&gt;: Failed to establish a new connection: [Errno 11001] getaddrinfo failed'))

During handling of the above exception, another exception occurred:

Traceback (most recent call last):
  File "D:\python_test\libs\ddt.py", line 145, in wrapper
    return func(self, *args, **kwargs)
  File "D:\python_test\cases\test_03_company.py", line 43, in test_company
    res = self.do_request.send(url=new_url,  # url地址
  File "D:\python_test\scripts\handle_request.py", line 57, in send
    res = self.one_session.request(method, url, params=data, **kwargs)
  File "D:\soft\python\lib\site-packages\requests\sessions.py", line 530, in request
    resp = self.send(prep, **send_kwargs)
  File "D:\soft\python\lib\site-packages\requests\sessions.py", line 643, in send
    r = adapter.send(request, **kwargs)
  File "D:\soft\python\lib\site-packages\requests\adapters.py", line 516, in send
    raise ConnectionError(e, request=request)
requests.exceptions.ConnectionError: HTTPConnectionPool(host='ssssss', port=9101): Max retries exceeded with url: /api/admin/buscompany/subcompany (Caused by NewConnectionError('&lt;urllib3.connection.HTTPConnection object at 0x0000024C2F6FF3A0&gt;: Failed to establish a new connection: [Errno 11001] getaddrinfo failed'))


    </pre>
    </div>
    </td>
</tr>

<tr id='ft3_4' class='none'>
    <td class='errorCase'><div class='testcase'>test_company_04: 编辑-公司名称为空</div></td>
    <td colspan='5' align='center'>
    <!--默认收起错误信息 -Findyou
    <button id='btn_ft3_4' type="button"  class="btn btn-danger btn-xs collapsed" data-toggle="collapse" data-target='#div_ft3_4'>错误</button>
    <div id='div_ft3_4' class="collapse">  -->
    <!-- 默认展开错误信息 -Findyou -->
    <button id='btn_ft3_4' type="button"  class="btn btn-danger btn-xs" data-toggle="collapse" data-target='#div_ft3_4'>错误</button>
    <div id='div_ft3_4' class="collapse in" align="left">
    <pre>
    
ft3_4: Traceback (most recent call last):
  File "D:\python_test\libs\ddt.py", line 145, in wrapper
    return func(self, *args, **kwargs)
  File "D:\python_test\cases\test_03_company.py", line 38, in test_company
    print(Parameterize.to_param(new_url))
  File "D:\python_test\scripts\handle_parameterize.py", line 48, in to_param
    invest_companyId = getattr(cls, 'companyId')
AttributeError: type object 'Parameterize' has no attribute 'companyId'


    </pre>
    </div>
    </td>
</tr>

<tr id='ft3_5' class='none'>
    <td class='errorCase'><div class='testcase'>test_company_05: 编辑-公司法人为空</div></td>
    <td colspan='5' align='center'>
    <!--默认收起错误信息 -Findyou
    <button id='btn_ft3_5' type="button"  class="btn btn-danger btn-xs collapsed" data-toggle="collapse" data-target='#div_ft3_5'>错误</button>
    <div id='div_ft3_5' class="collapse">  -->
    <!-- 默认展开错误信息 -Findyou -->
    <button id='btn_ft3_5' type="button"  class="btn btn-danger btn-xs" data-toggle="collapse" data-target='#div_ft3_5'>错误</button>
    <div id='div_ft3_5' class="collapse in" align="left">
    <pre>
    
ft3_5: Traceback (most recent call last):
  File "D:\python_test\libs\ddt.py", line 145, in wrapper
    return func(self, *args, **kwargs)
  File "D:\python_test\cases\test_03_company.py", line 38, in test_company
    print(Parameterize.to_param(new_url))
  File "D:\python_test\scripts\handle_parameterize.py", line 48, in to_param
    invest_companyId = getattr(cls, 'companyId')
AttributeError: type object 'Parameterize' has no attribute 'companyId'


    </pre>
    </div>
    </td>
</tr>

<tr id='ft3_6' class='none'>
    <td class='errorCase'><div class='testcase'>test_company_06: 编辑-法人电话为空</div></td>
    <td colspan='5' align='center'>
    <!--默认收起错误信息 -Findyou
    <button id='btn_ft3_6' type="button"  class="btn btn-danger btn-xs collapsed" data-toggle="collapse" data-target='#div_ft3_6'>错误</button>
    <div id='div_ft3_6' class="collapse">  -->
    <!-- 默认展开错误信息 -Findyou -->
    <button id='btn_ft3_6' type="button"  class="btn btn-danger btn-xs" data-toggle="collapse" data-target='#div_ft3_6'>错误</button>
    <div id='div_ft3_6' class="collapse in" align="left">
    <pre>
    
ft3_6: Traceback (most recent call last):
  File "D:\python_test\libs\ddt.py", line 145, in wrapper
    return func(self, *args, **kwargs)
  File "D:\python_test\cases\test_03_company.py", line 38, in test_company
    print(Parameterize.to_param(new_url))
  File "D:\python_test\scripts\handle_parameterize.py", line 48, in to_param
    invest_companyId = getattr(cls, 'companyId')
AttributeError: type object 'Parameterize' has no attribute 'companyId'


    </pre>
    </div>
    </td>
</tr>

<tr id='ft3_7' class='none'>
    <td class='errorCase'><div class='testcase'>test_company_07: 编辑-公司电话为空</div></td>
    <td colspan='5' align='center'>
    <!--默认收起错误信息 -Findyou
    <button id='btn_ft3_7' type="button"  class="btn btn-danger btn-xs collapsed" data-toggle="collapse" data-target='#div_ft3_7'>错误</button>
    <div id='div_ft3_7' class="collapse">  -->
    <!-- 默认展开错误信息 -Findyou -->
    <button id='btn_ft3_7' type="button"  class="btn btn-danger btn-xs" data-toggle="collapse" data-target='#div_ft3_7'>错误</button>
    <div id='div_ft3_7' class="collapse in" align="left">
    <pre>
    
ft3_7: Traceback (most recent call last):
  File "D:\python_test\libs\ddt.py", line 145, in wrapper
    return func(self, *args, **kwargs)
  File "D:\python_test\cases\test_03_company.py", line 38, in test_company
    print(Parameterize.to_param(new_url))
  File "D:\python_test\scripts\handle_parameterize.py", line 48, in to_param
    invest_companyId = getattr(cls, 'companyId')
AttributeError: type object 'Parameterize' has no attribute 'companyId'


    </pre>
    </div>
    </td>
</tr>

<tr id='ft3_8' class='none'>
    <td class='errorCase'><div class='testcase'>test_company_08: 编辑-公司地址为空</div></td>
    <td colspan='5' align='center'>
    <!--默认收起错误信息 -Findyou
    <button id='btn_ft3_8' type="button"  class="btn btn-danger btn-xs collapsed" data-toggle="collapse" data-target='#div_ft3_8'>错误</button>
    <div id='div_ft3_8' class="collapse">  -->
    <!-- 默认展开错误信息 -Findyou -->
    <button id='btn_ft3_8' type="button"  class="btn btn-danger btn-xs" data-toggle="collapse" data-target='#div_ft3_8'>错误</button>
    <div id='div_ft3_8' class="collapse in" align="left">
    <pre>
    
ft3_8: Traceback (most recent call last):
  File "D:\python_test\libs\ddt.py", line 145, in wrapper
    return func(self, *args, **kwargs)
  File "D:\python_test\cases\test_03_company.py", line 38, in test_company
    print(Parameterize.to_param(new_url))
  File "D:\python_test\scripts\handle_parameterize.py", line 48, in to_param
    invest_companyId = getattr(cls, 'companyId')
AttributeError: type object 'Parameterize' has no attribute 'companyId'


    </pre>
    </div>
    </td>
</tr>

<tr id='ft3_9' class='none'>
    <td class='errorCase'><div class='testcase'>test_company_09: 编辑-公司详细地址为空</div></td>
    <td colspan='5' align='center'>
    <!--默认收起错误信息 -Findyou
    <button id='btn_ft3_9' type="button"  class="btn btn-danger btn-xs collapsed" data-toggle="collapse" data-target='#div_ft3_9'>错误</button>
    <div id='div_ft3_9' class="collapse">  -->
    <!-- 默认展开错误信息 -Findyou -->
    <button id='btn_ft3_9' type="button"  class="btn btn-danger btn-xs" data-toggle="collapse" data-target='#div_ft3_9'>错误</button>
    <div id='div_ft3_9' class="collapse in" align="left">
    <pre>
    
ft3_9: Traceback (most recent call last):
  File "D:\python_test\libs\ddt.py", line 145, in wrapper
    return func(self, *args, **kwargs)
  File "D:\python_test\cases\test_03_company.py", line 38, in test_company
    print(Parameterize.to_param(new_url))
  File "D:\python_test\scripts\handle_parameterize.py", line 48, in to_param
    invest_companyId = getattr(cls, 'companyId')
AttributeError: type object 'Parameterize' has no attribute 'companyId'


    </pre>
    </div>
    </td>
</tr>

<tr id='ft3_10' class='none'>
    <td class='errorCase'><div class='testcase'>test_company_10: 编辑-公司统一社会信用代码为空</div></td>
    <td colspan='5' align='center'>
    <!--默认收起错误信息 -Findyou
    <button id='btn_ft3_10' type="button"  class="btn btn-danger btn-xs collapsed" data-toggle="collapse" data-target='#div_ft3_10'>错误</button>
    <div id='div_ft3_10' class="collapse">  -->
    <!-- 默认展开错误信息 -Findyou -->
    <button id='btn_ft3_10' type="button"  class="btn btn-danger btn-xs" data-toggle="collapse" data-target='#div_ft3_10'>错误</button>
    <div id='div_ft3_10' class="collapse in" align="left">
    <pre>
    
ft3_10: Traceback (most recent call last):
  File "D:\python_test\libs\ddt.py", line 145, in wrapper
    return func(self, *args, **kwargs)
  File "D:\python_test\cases\test_03_company.py", line 38, in test_company
    print(Parameterize.to_param(new_url))
  File "D:\python_test\scripts\handle_parameterize.py", line 48, in to_param
    invest_companyId = getattr(cls, 'companyId')
AttributeError: type object 'Parameterize' has no attribute 'companyId'


    </pre>
    </div>
    </td>
</tr>

<tr id='ft3_11' class='none'>
    <td class='errorCase'><div class='testcase'>test_company_11: 编辑-公司口号为空</div></td>
    <td colspan='5' align='center'>
    <!--默认收起错误信息 -Findyou
    <button id='btn_ft3_11' type="button"  class="btn btn-danger btn-xs collapsed" data-toggle="collapse" data-target='#div_ft3_11'>错误</button>
    <div id='div_ft3_11' class="collapse">  -->
    <!-- 默认展开错误信息 -Findyou -->
    <button id='btn_ft3_11' type="button"  class="btn btn-danger btn-xs" data-toggle="collapse" data-target='#div_ft3_11'>错误</button>
    <div id='div_ft3_11' class="collapse in" align="left">
    <pre>
    
ft3_11: Traceback (most recent call last):
  File "D:\python_test\libs\ddt.py", line 145, in wrapper
    return func(self, *args, **kwargs)
  File "D:\python_test\cases\test_03_company.py", line 38, in test_company
    print(Parameterize.to_param(new_url))
  File "D:\python_test\scripts\handle_parameterize.py", line 48, in to_param
    invest_companyId = getattr(cls, 'companyId')
AttributeError: type object 'Parameterize' has no attribute 'companyId'


    </pre>
    </div>
    </td>
</tr>

<tr id='ft3_12' class='none'>
    <td class='errorCase'><div class='testcase'>test_company_12: 编辑-公司简介为空</div></td>
    <td colspan='5' align='center'>
    <!--默认收起错误信息 -Findyou
    <button id='btn_ft3_12' type="button"  class="btn btn-danger btn-xs collapsed" data-toggle="collapse" data-target='#div_ft3_12'>错误</button>
    <div id='div_ft3_12' class="collapse">  -->
    <!-- 默认展开错误信息 -Findyou -->
    <button id='btn_ft3_12' type="button"  class="btn btn-danger btn-xs" data-toggle="collapse" data-target='#div_ft3_12'>错误</button>
    <div id='div_ft3_12' class="collapse in" align="left">
    <pre>
    
ft3_12: Traceback (most recent call last):
  File "D:\python_test\libs\ddt.py", line 145, in wrapper
    return func(self, *args, **kwargs)
  File "D:\python_test\cases\test_03_company.py", line 38, in test_company
    print(Parameterize.to_param(new_url))
  File "D:\python_test\scripts\handle_parameterize.py", line 48, in to_param
    invest_companyId = getattr(cls, 'companyId')
AttributeError: type object 'Parameterize' has no attribute 'companyId'


    </pre>
    </div>
    </td>
</tr>

<tr class='errorClass warning'>
    <td>test_04_supplier.TestProduct</td>
    <td class="text-center">11</td>
    <td class="text-center">0</td>
    <td class="text-center">0</td>
    <td class="text-center">11</td>
    <td class="text-center"><a href="javascript:showClassDetail('c4',11)" class="detail" id='c4'>详细</a></td>
</tr>

<tr id='ft4_1' class='none'>
    <td class='errorCase'><div class='testcase'>test_product_01: 正常登录</div></td>
    <td colspan='5' align='center'>
    <!--默认收起错误信息 -Findyou
    <button id='btn_ft4_1' type="button"  class="btn btn-danger btn-xs collapsed" data-toggle="collapse" data-target='#div_ft4_1'>错误</button>
    <div id='div_ft4_1' class="collapse">  -->
    <!-- 默认展开错误信息 -Findyou -->
    <button id='btn_ft4_1' type="button"  class="btn btn-danger btn-xs" data-toggle="collapse" data-target='#div_ft4_1'>错误</button>
    <div id='div_ft4_1' class="collapse in" align="left">
    <pre>
    
ft4_1: Traceback (most recent call last):
  File "D:\soft\python\lib\site-packages\urllib3\connection.py", line 159, in _new_conn
    conn = connection.create_connection(
  File "D:\soft\python\lib\site-packages\urllib3\util\connection.py", line 61, in create_connection
    for res in socket.getaddrinfo(host, port, family, socket.SOCK_STREAM):
  File "D:\soft\python\lib\socket.py", line 918, in getaddrinfo
    for res in _socket.getaddrinfo(host, port, family, type, proto, flags):
socket.gaierror: [Errno 11001] getaddrinfo failed

During handling of the above exception, another exception occurred:

Traceback (most recent call last):
  File "D:\soft\python\lib\site-packages\urllib3\connectionpool.py", line 670, in urlopen
    httplib_response = self._make_request(
  File "D:\soft\python\lib\site-packages\urllib3\connectionpool.py", line 392, in _make_request
    conn.request(method, url, **httplib_request_kw)
  File "D:\soft\python\lib\http\client.py", line 1230, in request
    self._send_request(method, url, body, headers, encode_chunked)
  File "D:\soft\python\lib\http\client.py", line 1276, in _send_request
    self.endheaders(body, encode_chunked=encode_chunked)
  File "D:\soft\python\lib\http\client.py", line 1225, in endheaders
    self._send_output(message_body, encode_chunked=encode_chunked)
  File "D:\soft\python\lib\http\client.py", line 1004, in _send_output
    self.send(msg)
  File "D:\soft\python\lib\http\client.py", line 944, in send
    self.connect()
  File "D:\soft\python\lib\site-packages\urllib3\connection.py", line 187, in connect
    conn = self._new_conn()
  File "D:\soft\python\lib\site-packages\urllib3\connection.py", line 171, in _new_conn
    raise NewConnectionError(
urllib3.exceptions.NewConnectionError: &lt;urllib3.connection.HTTPConnection object at 0x0000024C2F6FF6A0&gt;: Failed to establish a new connection: [Errno 11001] getaddrinfo failed

During handling of the above exception, another exception occurred:

Traceback (most recent call last):
  File "D:\soft\python\lib\site-packages\requests\adapters.py", line 439, in send
    resp = conn.urlopen(
  File "D:\soft\python\lib\site-packages\urllib3\connectionpool.py", line 724, in urlopen
    retries = retries.increment(
  File "D:\soft\python\lib\site-packages\urllib3\util\retry.py", line 439, in increment
    raise MaxRetryError(_pool, url, error or ResponseError(cause))
urllib3.exceptions.MaxRetryError: HTTPConnectionPool(host='ssssss', port=9101): Max retries exceeded with url: /api/auth/login (Caused by NewConnectionError('&lt;urllib3.connection.HTTPConnection object at 0x0000024C2F6FF6A0&gt;: Failed to establish a new connection: [Errno 11001] getaddrinfo failed'))

During handling of the above exception, another exception occurred:

Traceback (most recent call last):
  File "D:\python_test\libs\ddt.py", line 145, in wrapper
    return func(self, *args, **kwargs)
  File "D:\python_test\cases\test_04_supplier.py", line 46, in test_product
    res = self.do_request.send(url=new_url,  # url地址
  File "D:\python_test\scripts\handle_request.py", line 61, in send
    res = self.one_session.request(method, url, json=data, **kwargs)
  File "D:\soft\python\lib\site-packages\requests\sessions.py", line 530, in request
    resp = self.send(prep, **send_kwargs)
  File "D:\soft\python\lib\site-packages\requests\sessions.py", line 643, in send
    r = adapter.send(request, **kwargs)
  File "D:\soft\python\lib\site-packages\requests\adapters.py", line 516, in send
    raise ConnectionError(e, request=request)
requests.exceptions.ConnectionError: HTTPConnectionPool(host='ssssss', port=9101): Max retries exceeded with url: /api/auth/login (Caused by NewConnectionError('&lt;urllib3.connection.HTTPConnection object at 0x0000024C2F6FF6A0&gt;: Failed to establish a new connection: [Errno 11001] getaddrinfo failed'))


    </pre>
    </div>
    </td>
</tr>

<tr id='ft4_2' class='none'>
    <td class='errorCase'><div class='testcase'>test_product_02: 保存供应商为草稿</div></td>
    <td colspan='5' align='center'>
    <!--默认收起错误信息 -Findyou
    <button id='btn_ft4_2' type="button"  class="btn btn-danger btn-xs collapsed" data-toggle="collapse" data-target='#div_ft4_2'>错误</button>
    <div id='div_ft4_2' class="collapse">  -->
    <!-- 默认展开错误信息 -Findyou -->
    <button id='btn_ft4_2' type="button"  class="btn btn-danger btn-xs" data-toggle="collapse" data-target='#div_ft4_2'>错误</button>
    <div id='div_ft4_2' class="collapse in" align="left">
    <pre>
    
ft4_2: Traceback (most recent call last):
  File "D:\soft\python\lib\site-packages\urllib3\connection.py", line 159, in _new_conn
    conn = connection.create_connection(
  File "D:\soft\python\lib\site-packages\urllib3\util\connection.py", line 61, in create_connection
    for res in socket.getaddrinfo(host, port, family, socket.SOCK_STREAM):
  File "D:\soft\python\lib\socket.py", line 918, in getaddrinfo
    for res in _socket.getaddrinfo(host, port, family, type, proto, flags):
socket.gaierror: [Errno 11001] getaddrinfo failed

During handling of the above exception, another exception occurred:

Traceback (most recent call last):
  File "D:\soft\python\lib\site-packages\urllib3\connectionpool.py", line 670, in urlopen
    httplib_response = self._make_request(
  File "D:\soft\python\lib\site-packages\urllib3\connectionpool.py", line 392, in _make_request
    conn.request(method, url, **httplib_request_kw)
  File "D:\soft\python\lib\http\client.py", line 1230, in request
    self._send_request(method, url, body, headers, encode_chunked)
  File "D:\soft\python\lib\http\client.py", line 1276, in _send_request
    self.endheaders(body, encode_chunked=encode_chunked)
  File "D:\soft\python\lib\http\client.py", line 1225, in endheaders
    self._send_output(message_body, encode_chunked=encode_chunked)
  File "D:\soft\python\lib\http\client.py", line 1004, in _send_output
    self.send(msg)
  File "D:\soft\python\lib\http\client.py", line 944, in send
    self.connect()
  File "D:\soft\python\lib\site-packages\urllib3\connection.py", line 187, in connect
    conn = self._new_conn()
  File "D:\soft\python\lib\site-packages\urllib3\connection.py", line 171, in _new_conn
    raise NewConnectionError(
urllib3.exceptions.NewConnectionError: &lt;urllib3.connection.HTTPConnection object at 0x0000024C2F6FF790&gt;: Failed to establish a new connection: [Errno 11001] getaddrinfo failed

During handling of the above exception, another exception occurred:

Traceback (most recent call last):
  File "D:\soft\python\lib\site-packages\requests\adapters.py", line 439, in send
    resp = conn.urlopen(
  File "D:\soft\python\lib\site-packages\urllib3\connectionpool.py", line 724, in urlopen
    retries = retries.increment(
  File "D:\soft\python\lib\site-packages\urllib3\util\retry.py", line 439, in increment
    raise MaxRetryError(_pool, url, error or ResponseError(cause))
urllib3.exceptions.MaxRetryError: HTTPConnectionPool(host='ssssss', port=9101): Max retries exceeded with url: /api/crm/bussupplier/supplier (Caused by NewConnectionError('&lt;urllib3.connection.HTTPConnection object at 0x0000024C2F6FF790&gt;: Failed to establish a new connection: [Errno 11001] getaddrinfo failed'))

During handling of the above exception, another exception occurred:

Traceback (most recent call last):
  File "D:\python_test\libs\ddt.py", line 145, in wrapper
    return func(self, *args, **kwargs)
  File "D:\python_test\cases\test_04_supplier.py", line 46, in test_product
    res = self.do_request.send(url=new_url,  # url地址
  File "D:\python_test\scripts\handle_request.py", line 61, in send
    res = self.one_session.request(method, url, json=data, **kwargs)
  File "D:\soft\python\lib\site-packages\requests\sessions.py", line 530, in request
    resp = self.send(prep, **send_kwargs)
  File "D:\soft\python\lib\site-packages\requests\sessions.py", line 643, in send
    r = adapter.send(request, **kwargs)
  File "D:\soft\python\lib\site-packages\requests\adapters.py", line 516, in send
    raise ConnectionError(e, request=request)
requests.exceptions.ConnectionError: HTTPConnectionPool(host='ssssss', port=9101): Max retries exceeded with url: /api/crm/bussupplier/supplier (Caused by NewConnectionError('&lt;urllib3.connection.HTTPConnection object at 0x0000024C2F6FF790&gt;: Failed to establish a new connection: [Errno 11001] getaddrinfo failed'))


    </pre>
    </div>
    </td>
</tr>

<tr id='ft4_3' class='none'>
    <td class='errorCase'><div class='testcase'>test_product_03: 获取供应商列表</div></td>
    <td colspan='5' align='center'>
    <!--默认收起错误信息 -Findyou
    <button id='btn_ft4_3' type="button"  class="btn btn-danger btn-xs collapsed" data-toggle="collapse" data-target='#div_ft4_3'>错误</button>
    <div id='div_ft4_3' class="collapse">  -->
    <!-- 默认展开错误信息 -Findyou -->
    <button id='btn_ft4_3' type="button"  class="btn btn-danger btn-xs" data-toggle="collapse" data-target='#div_ft4_3'>错误</button>
    <div id='div_ft4_3' class="collapse in" align="left">
    <pre>
    
ft4_3: Traceback (most recent call last):
  File "D:\soft\python\lib\site-packages\urllib3\connection.py", line 159, in _new_conn
    conn = connection.create_connection(
  File "D:\soft\python\lib\site-packages\urllib3\util\connection.py", line 61, in create_connection
    for res in socket.getaddrinfo(host, port, family, socket.SOCK_STREAM):
  File "D:\soft\python\lib\socket.py", line 918, in getaddrinfo
    for res in _socket.getaddrinfo(host, port, family, type, proto, flags):
socket.gaierror: [Errno 11001] getaddrinfo failed

During handling of the above exception, another exception occurred:

Traceback (most recent call last):
  File "D:\soft\python\lib\site-packages\urllib3\connectionpool.py", line 670, in urlopen
    httplib_response = self._make_request(
  File "D:\soft\python\lib\site-packages\urllib3\connectionpool.py", line 392, in _make_request
    conn.request(method, url, **httplib_request_kw)
  File "D:\soft\python\lib\http\client.py", line 1230, in request
    self._send_request(method, url, body, headers, encode_chunked)
  File "D:\soft\python\lib\http\client.py", line 1276, in _send_request
    self.endheaders(body, encode_chunked=encode_chunked)
  File "D:\soft\python\lib\http\client.py", line 1225, in endheaders
    self._send_output(message_body, encode_chunked=encode_chunked)
  File "D:\soft\python\lib\http\client.py", line 1004, in _send_output
    self.send(msg)
  File "D:\soft\python\lib\http\client.py", line 944, in send
    self.connect()
  File "D:\soft\python\lib\site-packages\urllib3\connection.py", line 187, in connect
    conn = self._new_conn()
  File "D:\soft\python\lib\site-packages\urllib3\connection.py", line 171, in _new_conn
    raise NewConnectionError(
urllib3.exceptions.NewConnectionError: &lt;urllib3.connection.HTTPConnection object at 0x0000024C2F6FF790&gt;: Failed to establish a new connection: [Errno 11001] getaddrinfo failed

During handling of the above exception, another exception occurred:

Traceback (most recent call last):
  File "D:\soft\python\lib\site-packages\requests\adapters.py", line 439, in send
    resp = conn.urlopen(
  File "D:\soft\python\lib\site-packages\urllib3\connectionpool.py", line 724, in urlopen
    retries = retries.increment(
  File "D:\soft\python\lib\site-packages\urllib3\util\retry.py", line 439, in increment
    raise MaxRetryError(_pool, url, error or ResponseError(cause))
urllib3.exceptions.MaxRetryError: HTTPConnectionPool(host='ssssss', port=9101): Max retries exceeded with url: /api/crm/bussupplier/supplier?page=1&amp;perPage=20 (Caused by NewConnectionError('&lt;urllib3.connection.HTTPConnection object at 0x0000024C2F6FF790&gt;: Failed to establish a new connection: [Errno 11001] getaddrinfo failed'))

During handling of the above exception, another exception occurred:

Traceback (most recent call last):
  File "D:\python_test\libs\ddt.py", line 145, in wrapper
    return func(self, *args, **kwargs)
  File "D:\python_test\cases\test_04_supplier.py", line 46, in test_product
    res = self.do_request.send(url=new_url,  # url地址
  File "D:\python_test\scripts\handle_request.py", line 57, in send
    res = self.one_session.request(method, url, params=data, **kwargs)
  File "D:\soft\python\lib\site-packages\requests\sessions.py", line 530, in request
    resp = self.send(prep, **send_kwargs)
  File "D:\soft\python\lib\site-packages\requests\sessions.py", line 643, in send
    r = adapter.send(request, **kwargs)
  File "D:\soft\python\lib\site-packages\requests\adapters.py", line 516, in send
    raise ConnectionError(e, request=request)
requests.exceptions.ConnectionError: HTTPConnectionPool(host='ssssss', port=9101): Max retries exceeded with url: /api/crm/bussupplier/supplier?page=1&amp;perPage=20 (Caused by NewConnectionError('&lt;urllib3.connection.HTTPConnection object at 0x0000024C2F6FF790&gt;: Failed to establish a new connection: [Errno 11001] getaddrinfo failed'))


    </pre>
    </div>
    </td>
</tr>

<tr id='ft4_4' class='none'>
    <td class='errorCase'><div class='testcase'>test_product_04: 公司名称为空</div></td>
    <td colspan='5' align='center'>
    <!--默认收起错误信息 -Findyou
    <button id='btn_ft4_4' type="button"  class="btn btn-danger btn-xs collapsed" data-toggle="collapse" data-target='#div_ft4_4'>错误</button>
    <div id='div_ft4_4' class="collapse">  -->
    <!-- 默认展开错误信息 -Findyou -->
    <button id='btn_ft4_4' type="button"  class="btn btn-danger btn-xs" data-toggle="collapse" data-target='#div_ft4_4'>错误</button>
    <div id='div_ft4_4' class="collapse in" align="left">
    <pre>
    
ft4_4: 1396740097277169664
Traceback (most recent call last):
  File "D:\soft\python\lib\site-packages\urllib3\connection.py", line 159, in _new_conn
    conn = connection.create_connection(
  File "D:\soft\python\lib\site-packages\urllib3\util\connection.py", line 61, in create_connection
    for res in socket.getaddrinfo(host, port, family, socket.SOCK_STREAM):
  File "D:\soft\python\lib\socket.py", line 918, in getaddrinfo
    for res in _socket.getaddrinfo(host, port, family, type, proto, flags):
socket.gaierror: [Errno 11001] getaddrinfo failed

During handling of the above exception, another exception occurred:

Traceback (most recent call last):
  File "D:\soft\python\lib\site-packages\urllib3\connectionpool.py", line 670, in urlopen
    httplib_response = self._make_request(
  File "D:\soft\python\lib\site-packages\urllib3\connectionpool.py", line 392, in _make_request
    conn.request(method, url, **httplib_request_kw)
  File "D:\soft\python\lib\http\client.py", line 1230, in request
    self._send_request(method, url, body, headers, encode_chunked)
  File "D:\soft\python\lib\http\client.py", line 1276, in _send_request
    self.endheaders(body, encode_chunked=encode_chunked)
  File "D:\soft\python\lib\http\client.py", line 1225, in endheaders
    self._send_output(message_body, encode_chunked=encode_chunked)
  File "D:\soft\python\lib\http\client.py", line 1004, in _send_output
    self.send(msg)
  File "D:\soft\python\lib\http\client.py", line 944, in send
    self.connect()
  File "D:\soft\python\lib\site-packages\urllib3\connection.py", line 187, in connect
    conn = self._new_conn()
  File "D:\soft\python\lib\site-packages\urllib3\connection.py", line 171, in _new_conn
    raise NewConnectionError(
urllib3.exceptions.NewConnectionError: &lt;urllib3.connection.HTTPConnection object at 0x0000024C2F6FF940&gt;: Failed to establish a new connection: [Errno 11001] getaddrinfo failed

During handling of the above exception, another exception occurred:

Traceback (most recent call last):
  File "D:\soft\python\lib\site-packages\requests\adapters.py", line 439, in send
    resp = conn.urlopen(
  File "D:\soft\python\lib\site-packages\urllib3\connectionpool.py", line 724, in urlopen
    retries = retries.increment(
  File "D:\soft\python\lib\site-packages\urllib3\util\retry.py", line 439, in increment
    raise MaxRetryError(_pool, url, error or ResponseError(cause))
urllib3.exceptions.MaxRetryError: HTTPConnectionPool(host='ssssss', port=9101): Max retries exceeded with url: /api/crm/bussupplier/supplier1396740097277169664 (Caused by NewConnectionError('&lt;urllib3.connection.HTTPConnection object at 0x0000024C2F6FF940&gt;: Failed to establish a new connection: [Errno 11001] getaddrinfo failed'))

During handling of the above exception, another exception occurred:

Traceback (most recent call last):
  File "D:\python_test\libs\ddt.py", line 145, in wrapper
    return func(self, *args, **kwargs)
  File "D:\python_test\cases\test_04_supplier.py", line 46, in test_product
    res = self.do_request.send(url=new_url,  # url地址
  File "D:\python_test\scripts\handle_request.py", line 61, in send
    res = self.one_session.request(method, url, json=data, **kwargs)
  File "D:\soft\python\lib\site-packages\requests\sessions.py", line 530, in request
    resp = self.send(prep, **send_kwargs)
  File "D:\soft\python\lib\site-packages\requests\sessions.py", line 643, in send
    r = adapter.send(request, **kwargs)
  File "D:\soft\python\lib\site-packages\requests\adapters.py", line 516, in send
    raise ConnectionError(e, request=request)
requests.exceptions.ConnectionError: HTTPConnectionPool(host='ssssss', port=9101): Max retries exceeded with url: /api/crm/bussupplier/supplier1396740097277169664 (Caused by NewConnectionError('&lt;urllib3.connection.HTTPConnection object at 0x0000024C2F6FF940&gt;: Failed to establish a new connection: [Errno 11001] getaddrinfo failed'))


    </pre>
    </div>
    </td>
</tr>

<tr id='ft4_5' class='none'>
    <td class='errorCase'><div class='testcase'>test_product_05: 开户行名称为空</div></td>
    <td colspan='5' align='center'>
    <!--默认收起错误信息 -Findyou
    <button id='btn_ft4_5' type="button"  class="btn btn-danger btn-xs collapsed" data-toggle="collapse" data-target='#div_ft4_5'>错误</button>
    <div id='div_ft4_5' class="collapse">  -->
    <!-- 默认展开错误信息 -Findyou -->
    <button id='btn_ft4_5' type="button"  class="btn btn-danger btn-xs" data-toggle="collapse" data-target='#div_ft4_5'>错误</button>
    <div id='div_ft4_5' class="collapse in" align="left">
    <pre>
    
ft4_5: Traceback (most recent call last):
  File "D:\soft\python\lib\site-packages\urllib3\connection.py", line 159, in _new_conn
    conn = connection.create_connection(
  File "D:\soft\python\lib\site-packages\urllib3\util\connection.py", line 61, in create_connection
    for res in socket.getaddrinfo(host, port, family, socket.SOCK_STREAM):
  File "D:\soft\python\lib\socket.py", line 918, in getaddrinfo
    for res in _socket.getaddrinfo(host, port, family, type, proto, flags):
socket.gaierror: [Errno 11001] getaddrinfo failed

During handling of the above exception, another exception occurred:

Traceback (most recent call last):
  File "D:\soft\python\lib\site-packages\urllib3\connectionpool.py", line 670, in urlopen
    httplib_response = self._make_request(
  File "D:\soft\python\lib\site-packages\urllib3\connectionpool.py", line 392, in _make_request
    conn.request(method, url, **httplib_request_kw)
  File "D:\soft\python\lib\http\client.py", line 1230, in request
    self._send_request(method, url, body, headers, encode_chunked)
  File "D:\soft\python\lib\http\client.py", line 1276, in _send_request
    self.endheaders(body, encode_chunked=encode_chunked)
  File "D:\soft\python\lib\http\client.py", line 1225, in endheaders
    self._send_output(message_body, encode_chunked=encode_chunked)
  File "D:\soft\python\lib\http\client.py", line 1004, in _send_output
    self.send(msg)
  File "D:\soft\python\lib\http\client.py", line 944, in send
    self.connect()
  File "D:\soft\python\lib\site-packages\urllib3\connection.py", line 187, in connect
    conn = self._new_conn()
  File "D:\soft\python\lib\site-packages\urllib3\connection.py", line 171, in _new_conn
    raise NewConnectionError(
urllib3.exceptions.NewConnectionError: &lt;urllib3.connection.HTTPConnection object at 0x0000024C2F6FF790&gt;: Failed to establish a new connection: [Errno 11001] getaddrinfo failed

During handling of the above exception, another exception occurred:

Traceback (most recent call last):
  File "D:\soft\python\lib\site-packages\requests\adapters.py", line 439, in send
    resp = conn.urlopen(
  File "D:\soft\python\lib\site-packages\urllib3\connectionpool.py", line 724, in urlopen
    retries = retries.increment(
  File "D:\soft\python\lib\site-packages\urllib3\util\retry.py", line 439, in increment
    raise MaxRetryError(_pool, url, error or ResponseError(cause))
urllib3.exceptions.MaxRetryError: HTTPConnectionPool(host='ssssss', port=9101): Max retries exceeded with url: /api/crm/bussupplier/supplier (Caused by NewConnectionError('&lt;urllib3.connection.HTTPConnection object at 0x0000024C2F6FF790&gt;: Failed to establish a new connection: [Errno 11001] getaddrinfo failed'))

During handling of the above exception, another exception occurred:

Traceback (most recent call last):
  File "D:\python_test\libs\ddt.py", line 145, in wrapper
    return func(self, *args, **kwargs)
  File "D:\python_test\cases\test_04_supplier.py", line 46, in test_product
    res = self.do_request.send(url=new_url,  # url地址
  File "D:\python_test\scripts\handle_request.py", line 61, in send
    res = self.one_session.request(method, url, json=data, **kwargs)
  File "D:\soft\python\lib\site-packages\requests\sessions.py", line 530, in request
    resp = self.send(prep, **send_kwargs)
  File "D:\soft\python\lib\site-packages\requests\sessions.py", line 643, in send
    r = adapter.send(request, **kwargs)
  File "D:\soft\python\lib\site-packages\requests\adapters.py", line 516, in send
    raise ConnectionError(e, request=request)
requests.exceptions.ConnectionError: HTTPConnectionPool(host='ssssss', port=9101): Max retries exceeded with url: /api/crm/bussupplier/supplier (Caused by NewConnectionError('&lt;urllib3.connection.HTTPConnection object at 0x0000024C2F6FF790&gt;: Failed to establish a new connection: [Errno 11001] getaddrinfo failed'))


    </pre>
    </div>
    </td>
</tr>

<tr id='ft4_6' class='none'>
    <td class='errorCase'><div class='testcase'>test_product_06: 账户名称为空</div></td>
    <td colspan='5' align='center'>
    <!--默认收起错误信息 -Findyou
    <button id='btn_ft4_6' type="button"  class="btn btn-danger btn-xs collapsed" data-toggle="collapse" data-target='#div_ft4_6'>错误</button>
    <div id='div_ft4_6' class="collapse">  -->
    <!-- 默认展开错误信息 -Findyou -->
    <button id='btn_ft4_6' type="button"  class="btn btn-danger btn-xs" data-toggle="collapse" data-target='#div_ft4_6'>错误</button>
    <div id='div_ft4_6' class="collapse in" align="left">
    <pre>
    
ft4_6: Traceback (most recent call last):
  File "D:\soft\python\lib\site-packages\urllib3\connection.py", line 159, in _new_conn
    conn = connection.create_connection(
  File "D:\soft\python\lib\site-packages\urllib3\util\connection.py", line 61, in create_connection
    for res in socket.getaddrinfo(host, port, family, socket.SOCK_STREAM):
  File "D:\soft\python\lib\socket.py", line 918, in getaddrinfo
    for res in _socket.getaddrinfo(host, port, family, type, proto, flags):
socket.gaierror: [Errno 11001] getaddrinfo failed

During handling of the above exception, another exception occurred:

Traceback (most recent call last):
  File "D:\soft\python\lib\site-packages\urllib3\connectionpool.py", line 670, in urlopen
    httplib_response = self._make_request(
  File "D:\soft\python\lib\site-packages\urllib3\connectionpool.py", line 392, in _make_request
    conn.request(method, url, **httplib_request_kw)
  File "D:\soft\python\lib\http\client.py", line 1230, in request
    self._send_request(method, url, body, headers, encode_chunked)
  File "D:\soft\python\lib\http\client.py", line 1276, in _send_request
    self.endheaders(body, encode_chunked=encode_chunked)
  File "D:\soft\python\lib\http\client.py", line 1225, in endheaders
    self._send_output(message_body, encode_chunked=encode_chunked)
  File "D:\soft\python\lib\http\client.py", line 1004, in _send_output
    self.send(msg)
  File "D:\soft\python\lib\http\client.py", line 944, in send
    self.connect()
  File "D:\soft\python\lib\site-packages\urllib3\connection.py", line 187, in connect
    conn = self._new_conn()
  File "D:\soft\python\lib\site-packages\urllib3\connection.py", line 171, in _new_conn
    raise NewConnectionError(
urllib3.exceptions.NewConnectionError: &lt;urllib3.connection.HTTPConnection object at 0x0000024C2F6FF760&gt;: Failed to establish a new connection: [Errno 11001] getaddrinfo failed

During handling of the above exception, another exception occurred:

Traceback (most recent call last):
  File "D:\soft\python\lib\site-packages\requests\adapters.py", line 439, in send
    resp = conn.urlopen(
  File "D:\soft\python\lib\site-packages\urllib3\connectionpool.py", line 724, in urlopen
    retries = retries.increment(
  File "D:\soft\python\lib\site-packages\urllib3\util\retry.py", line 439, in increment
    raise MaxRetryError(_pool, url, error or ResponseError(cause))
urllib3.exceptions.MaxRetryError: HTTPConnectionPool(host='ssssss', port=9101): Max retries exceeded with url: /api/crm/bussupplier/supplier (Caused by NewConnectionError('&lt;urllib3.connection.HTTPConnection object at 0x0000024C2F6FF760&gt;: Failed to establish a new connection: [Errno 11001] getaddrinfo failed'))

During handling of the above exception, another exception occurred:

Traceback (most recent call last):
  File "D:\python_test\libs\ddt.py", line 145, in wrapper
    return func(self, *args, **kwargs)
  File "D:\python_test\cases\test_04_supplier.py", line 46, in test_product
    res = self.do_request.send(url=new_url,  # url地址
  File "D:\python_test\scripts\handle_request.py", line 61, in send
    res = self.one_session.request(method, url, json=data, **kwargs)
  File "D:\soft\python\lib\site-packages\requests\sessions.py", line 530, in request
    resp = self.send(prep, **send_kwargs)
  File "D:\soft\python\lib\site-packages\requests\sessions.py", line 643, in send
    r = adapter.send(request, **kwargs)
  File "D:\soft\python\lib\site-packages\requests\adapters.py", line 516, in send
    raise ConnectionError(e, request=request)
requests.exceptions.ConnectionError: HTTPConnectionPool(host='ssssss', port=9101): Max retries exceeded with url: /api/crm/bussupplier/supplier (Caused by NewConnectionError('&lt;urllib3.connection.HTTPConnection object at 0x0000024C2F6FF760&gt;: Failed to establish a new connection: [Errno 11001] getaddrinfo failed'))


    </pre>
    </div>
    </td>
</tr>

<tr id='ft4_7' class='none'>
    <td class='errorCase'><div class='testcase'>test_product_07: 开户行账号为空</div></td>
    <td colspan='5' align='center'>
    <!--默认收起错误信息 -Findyou
    <button id='btn_ft4_7' type="button"  class="btn btn-danger btn-xs collapsed" data-toggle="collapse" data-target='#div_ft4_7'>错误</button>
    <div id='div_ft4_7' class="collapse">  -->
    <!-- 默认展开错误信息 -Findyou -->
    <button id='btn_ft4_7' type="button"  class="btn btn-danger btn-xs" data-toggle="collapse" data-target='#div_ft4_7'>错误</button>
    <div id='div_ft4_7' class="collapse in" align="left">
    <pre>
    
ft4_7: Traceback (most recent call last):
  File "D:\soft\python\lib\site-packages\urllib3\connection.py", line 159, in _new_conn
    conn = connection.create_connection(
  File "D:\soft\python\lib\site-packages\urllib3\util\connection.py", line 61, in create_connection
    for res in socket.getaddrinfo(host, port, family, socket.SOCK_STREAM):
  File "D:\soft\python\lib\socket.py", line 918, in getaddrinfo
    for res in _socket.getaddrinfo(host, port, family, type, proto, flags):
socket.gaierror: [Errno 11001] getaddrinfo failed

During handling of the above exception, another exception occurred:

Traceback (most recent call last):
  File "D:\soft\python\lib\site-packages\urllib3\connectionpool.py", line 670, in urlopen
    httplib_response = self._make_request(
  File "D:\soft\python\lib\site-packages\urllib3\connectionpool.py", line 392, in _make_request
    conn.request(method, url, **httplib_request_kw)
  File "D:\soft\python\lib\http\client.py", line 1230, in request
    self._send_request(method, url, body, headers, encode_chunked)
  File "D:\soft\python\lib\http\client.py", line 1276, in _send_request
    self.endheaders(body, encode_chunked=encode_chunked)
  File "D:\soft\python\lib\http\client.py", line 1225, in endheaders
    self._send_output(message_body, encode_chunked=encode_chunked)
  File "D:\soft\python\lib\http\client.py", line 1004, in _send_output
    self.send(msg)
  File "D:\soft\python\lib\http\client.py", line 944, in send
    self.connect()
  File "D:\soft\python\lib\site-packages\urllib3\connection.py", line 187, in connect
    conn = self._new_conn()
  File "D:\soft\python\lib\site-packages\urllib3\connection.py", line 171, in _new_conn
    raise NewConnectionError(
urllib3.exceptions.NewConnectionError: &lt;urllib3.connection.HTTPConnection object at 0x0000024C2F6FF220&gt;: Failed to establish a new connection: [Errno 11001] getaddrinfo failed

During handling of the above exception, another exception occurred:

Traceback (most recent call last):
  File "D:\soft\python\lib\site-packages\requests\adapters.py", line 439, in send
    resp = conn.urlopen(
  File "D:\soft\python\lib\site-packages\urllib3\connectionpool.py", line 724, in urlopen
    retries = retries.increment(
  File "D:\soft\python\lib\site-packages\urllib3\util\retry.py", line 439, in increment
    raise MaxRetryError(_pool, url, error or ResponseError(cause))
urllib3.exceptions.MaxRetryError: HTTPConnectionPool(host='ssssss', port=9101): Max retries exceeded with url: /api/crm/bussupplier/supplier (Caused by NewConnectionError('&lt;urllib3.connection.HTTPConnection object at 0x0000024C2F6FF220&gt;: Failed to establish a new connection: [Errno 11001] getaddrinfo failed'))

During handling of the above exception, another exception occurred:

Traceback (most recent call last):
  File "D:\python_test\libs\ddt.py", line 145, in wrapper
    return func(self, *args, **kwargs)
  File "D:\python_test\cases\test_04_supplier.py", line 46, in test_product
    res = self.do_request.send(url=new_url,  # url地址
  File "D:\python_test\scripts\handle_request.py", line 61, in send
    res = self.one_session.request(method, url, json=data, **kwargs)
  File "D:\soft\python\lib\site-packages\requests\sessions.py", line 530, in request
    resp = self.send(prep, **send_kwargs)
  File "D:\soft\python\lib\site-packages\requests\sessions.py", line 643, in send
    r = adapter.send(request, **kwargs)
  File "D:\soft\python\lib\site-packages\requests\adapters.py", line 516, in send
    raise ConnectionError(e, request=request)
requests.exceptions.ConnectionError: HTTPConnectionPool(host='ssssss', port=9101): Max retries exceeded with url: /api/crm/bussupplier/supplier (Caused by NewConnectionError('&lt;urllib3.connection.HTTPConnection object at 0x0000024C2F6FF220&gt;: Failed to establish a new connection: [Errno 11001] getaddrinfo failed'))


    </pre>
    </div>
    </td>
</tr>

<tr id='ft4_8' class='none'>
    <td class='errorCase'><div class='testcase'>test_product_08: 联系人为空</div></td>
    <td colspan='5' align='center'>
    <!--默认收起错误信息 -Findyou
    <button id='btn_ft4_8' type="button"  class="btn btn-danger btn-xs collapsed" data-toggle="collapse" data-target='#div_ft4_8'>错误</button>
    <div id='div_ft4_8' class="collapse">  -->
    <!-- 默认展开错误信息 -Findyou -->
    <button id='btn_ft4_8' type="button"  class="btn btn-danger btn-xs" data-toggle="collapse" data-target='#div_ft4_8'>错误</button>
    <div id='div_ft4_8' class="collapse in" align="left">
    <pre>
    
ft4_8: Traceback (most recent call last):
  File "D:\soft\python\lib\site-packages\urllib3\connection.py", line 159, in _new_conn
    conn = connection.create_connection(
  File "D:\soft\python\lib\site-packages\urllib3\util\connection.py", line 61, in create_connection
    for res in socket.getaddrinfo(host, port, family, socket.SOCK_STREAM):
  File "D:\soft\python\lib\socket.py", line 918, in getaddrinfo
    for res in _socket.getaddrinfo(host, port, family, type, proto, flags):
socket.gaierror: [Errno 11001] getaddrinfo failed

During handling of the above exception, another exception occurred:

Traceback (most recent call last):
  File "D:\soft\python\lib\site-packages\urllib3\connectionpool.py", line 670, in urlopen
    httplib_response = self._make_request(
  File "D:\soft\python\lib\site-packages\urllib3\connectionpool.py", line 392, in _make_request
    conn.request(method, url, **httplib_request_kw)
  File "D:\soft\python\lib\http\client.py", line 1230, in request
    self._send_request(method, url, body, headers, encode_chunked)
  File "D:\soft\python\lib\http\client.py", line 1276, in _send_request
    self.endheaders(body, encode_chunked=encode_chunked)
  File "D:\soft\python\lib\http\client.py", line 1225, in endheaders
    self._send_output(message_body, encode_chunked=encode_chunked)
  File "D:\soft\python\lib\http\client.py", line 1004, in _send_output
    self.send(msg)
  File "D:\soft\python\lib\http\client.py", line 944, in send
    self.connect()
  File "D:\soft\python\lib\site-packages\urllib3\connection.py", line 187, in connect
    conn = self._new_conn()
  File "D:\soft\python\lib\site-packages\urllib3\connection.py", line 171, in _new_conn
    raise NewConnectionError(
urllib3.exceptions.NewConnectionError: &lt;urllib3.connection.HTTPConnection object at 0x0000024C2F6FF850&gt;: Failed to establish a new connection: [Errno 11001] getaddrinfo failed

During handling of the above exception, another exception occurred:

Traceback (most recent call last):
  File "D:\soft\python\lib\site-packages\requests\adapters.py", line 439, in send
    resp = conn.urlopen(
  File "D:\soft\python\lib\site-packages\urllib3\connectionpool.py", line 724, in urlopen
    retries = retries.increment(
  File "D:\soft\python\lib\site-packages\urllib3\util\retry.py", line 439, in increment
    raise MaxRetryError(_pool, url, error or ResponseError(cause))
urllib3.exceptions.MaxRetryError: HTTPConnectionPool(host='ssssss', port=9101): Max retries exceeded with url: /api/crm/bussupplier/supplier (Caused by NewConnectionError('&lt;urllib3.connection.HTTPConnection object at 0x0000024C2F6FF850&gt;: Failed to establish a new connection: [Errno 11001] getaddrinfo failed'))

During handling of the above exception, another exception occurred:

Traceback (most recent call last):
  File "D:\python_test\libs\ddt.py", line 145, in wrapper
    return func(self, *args, **kwargs)
  File "D:\python_test\cases\test_04_supplier.py", line 46, in test_product
    res = self.do_request.send(url=new_url,  # url地址
  File "D:\python_test\scripts\handle_request.py", line 61, in send
    res = self.one_session.request(method, url, json=data, **kwargs)
  File "D:\soft\python\lib\site-packages\requests\sessions.py", line 530, in request
    resp = self.send(prep, **send_kwargs)
  File "D:\soft\python\lib\site-packages\requests\sessions.py", line 643, in send
    r = adapter.send(request, **kwargs)
  File "D:\soft\python\lib\site-packages\requests\adapters.py", line 516, in send
    raise ConnectionError(e, request=request)
requests.exceptions.ConnectionError: HTTPConnectionPool(host='ssssss', port=9101): Max retries exceeded with url: /api/crm/bussupplier/supplier (Caused by NewConnectionError('&lt;urllib3.connection.HTTPConnection object at 0x0000024C2F6FF850&gt;: Failed to establish a new connection: [Errno 11001] getaddrinfo failed'))


    </pre>
    </div>
    </td>
</tr>

<tr id='ft4_9' class='none'>
    <td class='errorCase'><div class='testcase'>test_product_09: 收货地址为空</div></td>
    <td colspan='5' align='center'>
    <!--默认收起错误信息 -Findyou
    <button id='btn_ft4_9' type="button"  class="btn btn-danger btn-xs collapsed" data-toggle="collapse" data-target='#div_ft4_9'>错误</button>
    <div id='div_ft4_9' class="collapse">  -->
    <!-- 默认展开错误信息 -Findyou -->
    <button id='btn_ft4_9' type="button"  class="btn btn-danger btn-xs" data-toggle="collapse" data-target='#div_ft4_9'>错误</button>
    <div id='div_ft4_9' class="collapse in" align="left">
    <pre>
    
ft4_9: Traceback (most recent call last):
  File "D:\soft\python\lib\site-packages\urllib3\connection.py", line 159, in _new_conn
    conn = connection.create_connection(
  File "D:\soft\python\lib\site-packages\urllib3\util\connection.py", line 61, in create_connection
    for res in socket.getaddrinfo(host, port, family, socket.SOCK_STREAM):
  File "D:\soft\python\lib\socket.py", line 918, in getaddrinfo
    for res in _socket.getaddrinfo(host, port, family, type, proto, flags):
socket.gaierror: [Errno 11001] getaddrinfo failed

During handling of the above exception, another exception occurred:

Traceback (most recent call last):
  File "D:\soft\python\lib\site-packages\urllib3\connectionpool.py", line 670, in urlopen
    httplib_response = self._make_request(
  File "D:\soft\python\lib\site-packages\urllib3\connectionpool.py", line 392, in _make_request
    conn.request(method, url, **httplib_request_kw)
  File "D:\soft\python\lib\http\client.py", line 1230, in request
    self._send_request(method, url, body, headers, encode_chunked)
  File "D:\soft\python\lib\http\client.py", line 1276, in _send_request
    self.endheaders(body, encode_chunked=encode_chunked)
  File "D:\soft\python\lib\http\client.py", line 1225, in endheaders
    self._send_output(message_body, encode_chunked=encode_chunked)
  File "D:\soft\python\lib\http\client.py", line 1004, in _send_output
    self.send(msg)
  File "D:\soft\python\lib\http\client.py", line 944, in send
    self.connect()
  File "D:\soft\python\lib\site-packages\urllib3\connection.py", line 187, in connect
    conn = self._new_conn()
  File "D:\soft\python\lib\site-packages\urllib3\connection.py", line 171, in _new_conn
    raise NewConnectionError(
urllib3.exceptions.NewConnectionError: &lt;urllib3.connection.HTTPConnection object at 0x0000024C2F6FF820&gt;: Failed to establish a new connection: [Errno 11001] getaddrinfo failed

During handling of the above exception, another exception occurred:

Traceback (most recent call last):
  File "D:\soft\python\lib\site-packages\requests\adapters.py", line 439, in send
    resp = conn.urlopen(
  File "D:\soft\python\lib\site-packages\urllib3\connectionpool.py", line 724, in urlopen
    retries = retries.increment(
  File "D:\soft\python\lib\site-packages\urllib3\util\retry.py", line 439, in increment
    raise MaxRetryError(_pool, url, error or ResponseError(cause))
urllib3.exceptions.MaxRetryError: HTTPConnectionPool(host='ssssss', port=9101): Max retries exceeded with url: /api/crm/bussupplier/supplier (Caused by NewConnectionError('&lt;urllib3.connection.HTTPConnection object at 0x0000024C2F6FF820&gt;: Failed to establish a new connection: [Errno 11001] getaddrinfo failed'))

During handling of the above exception, another exception occurred:

Traceback (most recent call last):
  File "D:\python_test\libs\ddt.py", line 145, in wrapper
    return func(self, *args, **kwargs)
  File "D:\python_test\cases\test_04_supplier.py", line 46, in test_product
    res = self.do_request.send(url=new_url,  # url地址
  File "D:\python_test\scripts\handle_request.py", line 61, in send
    res = self.one_session.request(method, url, json=data, **kwargs)
  File "D:\soft\python\lib\site-packages\requests\sessions.py", line 530, in request
    resp = self.send(prep, **send_kwargs)
  File "D:\soft\python\lib\site-packages\requests\sessions.py", line 643, in send
    r = adapter.send(request, **kwargs)
  File "D:\soft\python\lib\site-packages\requests\adapters.py", line 516, in send
    raise ConnectionError(e, request=request)
requests.exceptions.ConnectionError: HTTPConnectionPool(host='ssssss', port=9101): Max retries exceeded with url: /api/crm/bussupplier/supplier (Caused by NewConnectionError('&lt;urllib3.connection.HTTPConnection object at 0x0000024C2F6FF820&gt;: Failed to establish a new connection: [Errno 11001] getaddrinfo failed'))


    </pre>
    </div>
    </td>
</tr>

<tr id='ft4_10' class='none'>
    <td class='errorCase'><div class='testcase'>test_product_10: 收票地址为空</div></td>
    <td colspan='5' align='center'>
    <!--默认收起错误信息 -Findyou
    <button id='btn_ft4_10' type="button"  class="btn btn-danger btn-xs collapsed" data-toggle="collapse" data-target='#div_ft4_10'>错误</button>
    <div id='div_ft4_10' class="collapse">  -->
    <!-- 默认展开错误信息 -Findyou -->
    <button id='btn_ft4_10' type="button"  class="btn btn-danger btn-xs" data-toggle="collapse" data-target='#div_ft4_10'>错误</button>
    <div id='div_ft4_10' class="collapse in" align="left">
    <pre>
    
ft4_10: Traceback (most recent call last):
  File "D:\soft\python\lib\site-packages\urllib3\connection.py", line 159, in _new_conn
    conn = connection.create_connection(
  File "D:\soft\python\lib\site-packages\urllib3\util\connection.py", line 61, in create_connection
    for res in socket.getaddrinfo(host, port, family, socket.SOCK_STREAM):
  File "D:\soft\python\lib\socket.py", line 918, in getaddrinfo
    for res in _socket.getaddrinfo(host, port, family, type, proto, flags):
socket.gaierror: [Errno 11001] getaddrinfo failed

During handling of the above exception, another exception occurred:

Traceback (most recent call last):
  File "D:\soft\python\lib\site-packages\urllib3\connectionpool.py", line 670, in urlopen
    httplib_response = self._make_request(
  File "D:\soft\python\lib\site-packages\urllib3\connectionpool.py", line 392, in _make_request
    conn.request(method, url, **httplib_request_kw)
  File "D:\soft\python\lib\http\client.py", line 1230, in request
    self._send_request(method, url, body, headers, encode_chunked)
  File "D:\soft\python\lib\http\client.py", line 1276, in _send_request
    self.endheaders(body, encode_chunked=encode_chunked)
  File "D:\soft\python\lib\http\client.py", line 1225, in endheaders
    self._send_output(message_body, encode_chunked=encode_chunked)
  File "D:\soft\python\lib\http\client.py", line 1004, in _send_output
    self.send(msg)
  File "D:\soft\python\lib\http\client.py", line 944, in send
    self.connect()
  File "D:\soft\python\lib\site-packages\urllib3\connection.py", line 187, in connect
    conn = self._new_conn()
  File "D:\soft\python\lib\site-packages\urllib3\connection.py", line 171, in _new_conn
    raise NewConnectionError(
urllib3.exceptions.NewConnectionError: &lt;urllib3.connection.HTTPConnection object at 0x0000024C2F6FF7C0&gt;: Failed to establish a new connection: [Errno 11001] getaddrinfo failed

During handling of the above exception, another exception occurred:

Traceback (most recent call last):
  File "D:\soft\python\lib\site-packages\requests\adapters.py", line 439, in send
    resp = conn.urlopen(
  File "D:\soft\python\lib\site-packages\urllib3\connectionpool.py", line 724, in urlopen
    retries = retries.increment(
  File "D:\soft\python\lib\site-packages\urllib3\util\retry.py", line 439, in increment
    raise MaxRetryError(_pool, url, error or ResponseError(cause))
urllib3.exceptions.MaxRetryError: HTTPConnectionPool(host='ssssss', port=9101): Max retries exceeded with url: /api/crm/bussupplier/supplier (Caused by NewConnectionError('&lt;urllib3.connection.HTTPConnection object at 0x0000024C2F6FF7C0&gt;: Failed to establish a new connection: [Errno 11001] getaddrinfo failed'))

During handling of the above exception, another exception occurred:

Traceback (most recent call last):
  File "D:\python_test\libs\ddt.py", line 145, in wrapper
    return func(self, *args, **kwargs)
  File "D:\python_test\cases\test_04_supplier.py", line 46, in test_product
    res = self.do_request.send(url=new_url,  # url地址
  File "D:\python_test\scripts\handle_request.py", line 61, in send
    res = self.one_session.request(method, url, json=data, **kwargs)
  File "D:\soft\python\lib\site-packages\requests\sessions.py", line 530, in request
    resp = self.send(prep, **send_kwargs)
  File "D:\soft\python\lib\site-packages\requests\sessions.py", line 643, in send
    r = adapter.send(request, **kwargs)
  File "D:\soft\python\lib\site-packages\requests\adapters.py", line 516, in send
    raise ConnectionError(e, request=request)
requests.exceptions.ConnectionError: HTTPConnectionPool(host='ssssss', port=9101): Max retries exceeded with url: /api/crm/bussupplier/supplier (Caused by NewConnectionError('&lt;urllib3.connection.HTTPConnection object at 0x0000024C2F6FF7C0&gt;: Failed to establish a new connection: [Errno 11001] getaddrinfo failed'))


    </pre>
    </div>
    </td>
</tr>

<tr id='ft4_11' class='none'>
    <td class='errorCase'><div class='testcase'>test_product_11: 删除供应商</div></td>
    <td colspan='5' align='center'>
    <!--默认收起错误信息 -Findyou
    <button id='btn_ft4_11' type="button"  class="btn btn-danger btn-xs collapsed" data-toggle="collapse" data-target='#div_ft4_11'>错误</button>
    <div id='div_ft4_11' class="collapse">  -->
    <!-- 默认展开错误信息 -Findyou -->
    <button id='btn_ft4_11' type="button"  class="btn btn-danger btn-xs" data-toggle="collapse" data-target='#div_ft4_11'>错误</button>
    <div id='div_ft4_11' class="collapse in" align="left">
    <pre>
    
ft4_11: Traceback (most recent call last):
  File "D:\soft\python\lib\site-packages\urllib3\connection.py", line 159, in _new_conn
    conn = connection.create_connection(
  File "D:\soft\python\lib\site-packages\urllib3\util\connection.py", line 61, in create_connection
    for res in socket.getaddrinfo(host, port, family, socket.SOCK_STREAM):
  File "D:\soft\python\lib\socket.py", line 918, in getaddrinfo
    for res in _socket.getaddrinfo(host, port, family, type, proto, flags):
socket.gaierror: [Errno 11001] getaddrinfo failed

During handling of the above exception, another exception occurred:

Traceback (most recent call last):
  File "D:\soft\python\lib\site-packages\urllib3\connectionpool.py", line 670, in urlopen
    httplib_response = self._make_request(
  File "D:\soft\python\lib\site-packages\urllib3\connectionpool.py", line 392, in _make_request
    conn.request(method, url, **httplib_request_kw)
  File "D:\soft\python\lib\http\client.py", line 1230, in request
    self._send_request(method, url, body, headers, encode_chunked)
  File "D:\soft\python\lib\http\client.py", line 1276, in _send_request
    self.endheaders(body, encode_chunked=encode_chunked)
  File "D:\soft\python\lib\http\client.py", line 1225, in endheaders
    self._send_output(message_body, encode_chunked=encode_chunked)
  File "D:\soft\python\lib\http\client.py", line 1004, in _send_output
    self.send(msg)
  File "D:\soft\python\lib\http\client.py", line 944, in send
    self.connect()
  File "D:\soft\python\lib\site-packages\urllib3\connection.py", line 187, in connect
    conn = self._new_conn()
  File "D:\soft\python\lib\site-packages\urllib3\connection.py", line 171, in _new_conn
    raise NewConnectionError(
urllib3.exceptions.NewConnectionError: &lt;urllib3.connection.HTTPConnection object at 0x0000024C2F6FF790&gt;: Failed to establish a new connection: [Errno 11001] getaddrinfo failed

During handling of the above exception, another exception occurred:

Traceback (most recent call last):
  File "D:\soft\python\lib\site-packages\requests\adapters.py", line 439, in send
    resp = conn.urlopen(
  File "D:\soft\python\lib\site-packages\urllib3\connectionpool.py", line 724, in urlopen
    retries = retries.increment(
  File "D:\soft\python\lib\site-packages\urllib3\util\retry.py", line 439, in increment
    raise MaxRetryError(_pool, url, error or ResponseError(cause))
urllib3.exceptions.MaxRetryError: HTTPConnectionPool(host='ssssss', port=9101): Max retries exceeded with url: /api/crm/bussupplier/supplier (Caused by NewConnectionError('&lt;urllib3.connection.HTTPConnection object at 0x0000024C2F6FF790&gt;: Failed to establish a new connection: [Errno 11001] getaddrinfo failed'))

During handling of the above exception, another exception occurred:

Traceback (most recent call last):
  File "D:\python_test\libs\ddt.py", line 145, in wrapper
    return func(self, *args, **kwargs)
  File "D:\python_test\cases\test_04_supplier.py", line 46, in test_product
    res = self.do_request.send(url=new_url,  # url地址
  File "D:\python_test\scripts\handle_request.py", line 61, in send
    res = self.one_session.request(method, url, json=data, **kwargs)
  File "D:\soft\python\lib\site-packages\requests\sessions.py", line 530, in request
    resp = self.send(prep, **send_kwargs)
  File "D:\soft\python\lib\site-packages\requests\sessions.py", line 643, in send
    r = adapter.send(request, **kwargs)
  File "D:\soft\python\lib\site-packages\requests\adapters.py", line 516, in send
    raise ConnectionError(e, request=request)
requests.exceptions.ConnectionError: HTTPConnectionPool(host='ssssss', port=9101): Max retries exceeded with url: /api/crm/bussupplier/supplier (Caused by NewConnectionError('&lt;urllib3.connection.HTTPConnection object at 0x0000024C2F6FF790&gt;: Failed to establish a new connection: [Errno 11001] getaddrinfo failed'))


    </pre>
    </div>
    </td>
</tr>

<tr id='total_row' class="text-center active">
    <td>总计</td>
    <td>33</td>
    <td>0</td>
    <td>0</td>
    <td>33</td>
    <td>通过率：0.00%</td>
</tr>
</table>

<div id='ending'>&nbsp;</div>
    <div style=" position:fixed;right:50px; bottom:30px; width:20px; height:20px;cursor:pointer">
    <a href="#"><span class="glyphicon glyphicon-eject" style = "font-size:30px;" aria-hidden="true">
    </span></a></div>
    
</body>
</html>
